Workbook

Sheet DEMATEL
A1: Ma trận quan hệ trực tiếp DRM
A3: L | B3: DRI1 | C3: DRI3 | D3: DRI4 | E3: DRI5 | F3: DRI6 | G3: DRI7 | H3: DRI9 | I3: DRI10 | J3: DRI11 | K3: DRI13 | L3: DRI14 | M3: DRI15 | O3: M | P3: DRI1 | Q3: DRI3 | R3: DRI4 | S3: DRI5 | T3: DRI6 | U3: DRI7 | V3: DRI9 | W3: DRI10 | X3: DRI11 | Y3: DRI13 | Z3: DRI14 | AA3: DRI15 | AC3: U | AD3: DRI1 | AE3: DRI3 | AF3: DRI4 | AG3: DRI5 | AH3: DRI6 | AI3: DRI7 | AJ3: DRI9 | AK3: DRI10 | AL3: DRI11 | AM3: DRI13 | AN3: DRI14 | AO3: DRI15
A4: DRI1 | B4: =AVERAGE('Ans 1:Ans 40'!B30) -> 0 | C4: =AVERAGE('Ans 1:Ans 40'!C30) -> 0.163025 | D4: =AVERAGE('Ans 1:Ans 40'!D30) -> 0.16316 | E4: =AVERAGE('Ans 1:Ans 40'!E30) -> 0.034735 | F4: =AVERAGE('Ans 1:Ans 40'!F30) -> 0.0734375 | G4: =AVERAGE('Ans 1:Ans 40'!G30) -> 0.0384 | H4: =AVERAGE('Ans 1:Ans 40'!H30) -> 0.05491 | I4: =AVERAGE('Ans 1:Ans 40'!I30) -> 0.0365875 | ... M4: =AVERAGE('Ans 1:Ans 40'!M30) -> 0.048165 | O4: DRI1 | P4: =AVERAGE('Ans 1:Ans 40'!B44) -> 0 | Q4: =AVERAGE('Ans 1:Ans 40'!C44) -> 0.25099 | R4: =AVERAGE('Ans 1:Ans 40'!D44) -> 0.251045 | S4: =AVERAGE('Ans 1:Ans 40'!E44) -> 0.084455 | T4: =AVERAGE('Ans 1:Ans 40'!F44) -> 0.1281025 | U4: =AVERAGE('Ans 1:Ans 40'!G44) -> 0.0769025 | V4: =AVERAGE('Ans 1:Ans 40'!H44) -> 0.09679 | W4: =AVERAGE('Ans 1:Ans 40'!I44) -> 0.068995 | ... AA4: =AVERAGE('Ans 1:Ans 40'!M44) -> 0.0952 | AC4: DRI1 | AD4: =AVERAGE('Ans 1:Ans 40'!B58) -> 0 | AE4: =AVERAGE('Ans 1:Ans 40'!C58) -> 0.33896 | AF4: =AVERAGE('Ans 1:Ans 40'!D58) -> 0.338945 | AG4: =AVERAGE('Ans 1:Ans 40'!E58) -> 0.1577975 | AH4: =AVERAGE('Ans 1:Ans 40'!F58) -> 0.202535 | AI4: =AVERAGE('Ans 1:Ans 40'!G58) -> 0.13852 | AJ4: =AVERAGE('Ans 1:Ans 40'!H58) -> 0.1623025 | AK4: =AVERAGE('Ans 1:Ans 40'!I58) -> 0.1281875 | ... AO4: =AVERAGE('Ans 1:Ans 40'!M58) -> 0.1538375
A5: DRI3 | B5: =AVERAGE('Ans 1:Ans 40'!B31) -> 0.0300475 | C5: =AVERAGE('Ans 1:Ans 40'!C31) -> 0 | D5: =AVERAGE('Ans 1:Ans 40'!D31) -> 0.2570725 | E5: =AVERAGE('Ans 1:Ans 40'!E31) -> 0.225905 | F5: =AVERAGE('Ans 1:Ans 40'!F31) -> 0.0600125 | G5: =AVERAGE('Ans 1:Ans 40'!G31) -> 0.1691475 | H5: =AVERAGE('Ans 1:Ans 40'!H31) -> 0.168805 | I5: =AVERAGE('Ans 1:Ans 40'!I31) -> 0.017675 | ... M5: =AVERAGE('Ans 1:Ans 40'!M31) -> 0.2106275 | O5: DRI3 | P5: =AVERAGE('Ans 1:Ans 40'!B45) -> 0.09268 | Q5: =AVERAGE('Ans 1:Ans 40'!C45) -> 0 | R5: =AVERAGE('Ans 1:Ans 40'!D45) -> 0.3483325 | S5: =AVERAGE('Ans 1:Ans 40'!E45) -> 0.30836 | T5: =AVERAGE('Ans 1:Ans 40'!F45) -> 0.125205 | U5: =AVERAGE('Ans 1:Ans 40'!G45) -> 0.235305 | V5: =AVERAGE('Ans 1:Ans 40'!H45) -> 0.237935 | W5: =AVERAGE('Ans 1:Ans 40'!I45) -> 0.0645975 | ... AA5: =AVERAGE('Ans 1:Ans 40'!M45) -> 0.301755 | AC5: DRI3 | AD5: =AVERAGE('Ans 1:Ans 40'!B59) -> 0.1552925 | AE5: =AVERAGE('Ans 1:Ans 40'!C59) -> 0 | AF5: =AVERAGE('Ans 1:Ans 40'!D59) -> 0.36494 | AG5: =AVERAGE('Ans 1:Ans 40'!E59) -> 0.325495 | AH5: =AVERAGE('Ans 1:Ans 40'!F59) -> 0.1998325 | AI5: =AVERAGE('Ans 1:Ans 40'!G59) -> 0.2682475 | AJ5: =AVERAGE('Ans 1:Ans 40'!H59) -> 0.272995 | AK5: =AVERAGE('Ans 1:Ans 40'!I59) -> 0.12939 | ... AO5: =AVERAGE('Ans 1:Ans 40'!M59) -> 0.36618
A6: DRI4 | B6: =AVERAGE('Ans 1:Ans 40'!B32) -> 0.0701125 | C6: =AVERAGE('Ans 1:Ans 40'!C32) -> 0.00386 | D6: =AVERAGE('Ans 1:Ans 40'!D32) -> 0 | E6: =AVERAGE('Ans 1:Ans 40'!E32) -> 0.0770325 | F6: =AVERAGE('Ans 1:Ans 40'!F32) -> 0.003535 | G6: =AVERAGE('Ans 1:Ans 40'!G32) -> 0.0723475 | H6: =AVERAGE('Ans 1:Ans 40'!H32) -> 0.076065 | I6: =AVERAGE('Ans 1:Ans 40'!I32) -> 0.0123725 | ... M6: =AVERAGE('Ans 1:Ans 40'!M32) -> 0.21705 | O6: DRI4 | P6: =AVERAGE('Ans 1:Ans 40'!B46) -> 0.12969 | Q6: =AVERAGE('Ans 1:Ans 40'!C46) -> 0.02427 | R6: =AVERAGE('Ans 1:Ans 40'!D46) -> 0 | S6: =AVERAGE('Ans 1:Ans 40'!E46) -> 0.1299425 | T6: =AVERAGE('Ans 1:Ans 40'!F46) -> 0.0447475 | U6: =AVERAGE('Ans 1:Ans 40'!G46) -> 0.129585 | V6: =AVERAGE('Ans 1:Ans 40'!H46) -> 0.1411925 | W6: =AVERAGE('Ans 1:Ans 40'!I46) -> 0.0490875 | ... AA6: =AVERAGE('Ans 1:Ans 40'!M46) -> 0.31139 | AC6: DRI4 | AD6: =AVERAGE('Ans 1:Ans 40'!B60) -> 0.201825 | AE6: =AVERAGE('Ans 1:Ans 40'!C60) -> 0.0904 | AF6: =AVERAGE('Ans 1:Ans 40'!D60) -> 0 | AG6: =AVERAGE('Ans 1:Ans 40'!E60) -> 0.2035975 | AH6: =AVERAGE('Ans 1:Ans 40'!F60) -> 0.105155 | AI6: =AVERAGE('Ans 1:Ans 40'!G60) -> 0.19853 | AJ6: =AVERAGE('Ans 1:Ans 40'!H60) -> 0.213975 | AK6: =AVERAGE('Ans 1:Ans 40'!I60) -> 0.1138825 | ... AO6: =AVERAGE('Ans 1:Ans 40'!M60) -> 0.37726
A7: DRI5 | B7: =AVERAGE('Ans 1:Ans 40'!B33) -> 0.0756525 | C7: =AVERAGE('Ans 1:Ans 40'!C33) -> 0.0797375 | D7: =AVERAGE('Ans 1:Ans 40'!D33) -> 0.073695 | E7: =AVERAGE('Ans 1:Ans 40'!E33) -> 0 | F7: =AVERAGE('Ans 1:Ans 40'!F33) -> 0.0693075 | G7: =AVERAGE('Ans 1:Ans 40'!G33) -> 0.08281 | H7: =AVERAGE('Ans 1:Ans 40'!H33) -> 0.1955375 | I7: =AVERAGE('Ans 1:Ans 40'!I33) -> 0.060495 | ... M7: =AVERAGE('Ans 1:Ans 40'!M33) -> 0.1477225 | O7: DRI5 | P7: =AVERAGE('Ans 1:Ans 40'!B47) -> 0.1259725 | Q7: =AVERAGE('Ans 1:Ans 40'!C47) -> 0.13125 | R7: =AVERAGE('Ans 1:Ans 40'!D47) -> 0.1275225 | S7: =AVERAGE('Ans 1:Ans 40'!E47) -> 0 | T7: =AVERAGE('Ans 1:Ans 40'!F47) -> 0.1304425 | U7: =AVERAGE('Ans 1:Ans 40'!G47) -> 0.13864 | V7: =AVERAGE('Ans 1:Ans 40'!H47) -> 0.284145 | W7: =AVERAGE('Ans 1:Ans 40'!I47) -> 0.11184 | ... AA7: =AVERAGE('Ans 1:Ans 40'!M47) -> 0.2215375 | AC7: DRI5 | AD7: =AVERAGE('Ans 1:Ans 40'!B61) -> 0.18029 | AE7: =AVERAGE('Ans 1:Ans 40'!C61) -> 0.1841675 | AF7: =AVERAGE('Ans 1:Ans 40'!D61) -> 0.1836125 | AG7: =AVERAGE('Ans 1:Ans 40'!E61) -> 0 | AH7: =AVERAGE('Ans 1:Ans 40'!F61) -> 0.2041525 | AI7: =AVERAGE('Ans 1:Ans 40'!G61) -> 0.1955825 | AJ7: =AVERAGE('Ans 1:Ans 40'!H61) -> 0.3561 | AK7: =AVERAGE('Ans 1:Ans 40'!I61) -> 0.175255 | ... AO7: =AVERAGE('Ans 1:Ans 40'!M61) -> 0.280665
A8: DRI6 | B8: =AVERAGE('Ans 1:Ans 40'!B34) -> 0.00386 | C8: =AVERAGE('Ans 1:Ans 40'!C34) -> 0.00707 | D8: =AVERAGE('Ans 1:Ans 40'!D34) -> 0.0056275 | E8: =AVERAGE('Ans 1:Ans 40'!E34) -> 0.0053025 | F8: =AVERAGE('Ans 1:Ans 40'!F34) -> 0 | G8: =AVERAGE('Ans 1:Ans 40'!G34) -> 0.177395 | H8: =AVERAGE('Ans 1:Ans 40'!H34) -> 0.009485 | I8: =AVERAGE('Ans 1:Ans 40'!I34) -> 0.0123725 | ... M8: =AVERAGE('Ans 1:Ans 40'!M34) -> 0.0088375 | O8: DRI6 | P8: =AVERAGE('Ans 1:Ans 40'!B48) -> 0.0375625 | Q8: =AVERAGE('Ans 1:Ans 40'!C48) -> 0.0490825 | R8: =AVERAGE('Ans 1:Ans 40'!D48) -> 0.0302875 | S8: =AVERAGE('Ans 1:Ans 40'!E48) -> 0.0363825 | T8: =AVERAGE('Ans 1:Ans 40'!F48) -> 0 | U8: =AVERAGE('Ans 1:Ans 40'!G48) -> 0.263585 | V8: =AVERAGE('Ans 1:Ans 40'!H48) -> 0.0495925 | W8: =AVERAGE('Ans 1:Ans 40'!I48) -> 0.0526225 | ... AA8: =AVERAGE('Ans 1:Ans 40'!M48) -> 0.04627 | AC8: DRI6 | AD8: =AVERAGE('Ans 1:Ans 40'!B62) -> 0.09591 | AE8: =AVERAGE('Ans 1:Ans 40'!C62) -> 0.112465 | AF8: =AVERAGE('Ans 1:Ans 40'!D62) -> 0.0919675 | AG8: =AVERAGE('Ans 1:Ans 40'!E62) -> 0.096245 | AH8: =AVERAGE('Ans 1:Ans 40'!F62) -> 0 | AI8: =AVERAGE('Ans 1:Ans 40'!G62) -> 0.31967 | AJ8: =AVERAGE('Ans 1:Ans 40'!H62) -> 0.116835 | AK8: =AVERAGE('Ans 1:Ans 40'!I62) -> 0.1179975 | ... AO8: =AVERAGE('Ans 1:Ans 40'!M62) -> 0.1107
A9: DRI7 | B9: =AVERAGE('Ans 1:Ans 40'!B35) -> 0.007395 | C9: =AVERAGE('Ans 1:Ans 40'!C35) -> 0.00707 | D9: =AVERAGE('Ans 1:Ans 40'!D35) -> 0.003535 | E9: =AVERAGE('Ans 1:Ans 40'!E35) -> 0.00707 | F9: =AVERAGE('Ans 1:Ans 40'!F35) -> 0.0053025 | G9: =AVERAGE('Ans 1:Ans 40'!G35) -> 0 | H9: =AVERAGE('Ans 1:Ans 40'!H35) -> 0.0056275 | I9: =AVERAGE('Ans 1:Ans 40'!I35) -> 0.0091625 | ... M9: =AVERAGE('Ans 1:Ans 40'!M35) -> 0.0053025 | O9: DRI7 | P9: =AVERAGE('Ans 1:Ans 40'!B49) -> 0.04198 | Q9: =AVERAGE('Ans 1:Ans 40'!C49) -> 0.038075 | R9: =AVERAGE('Ans 1:Ans 40'!D49) -> 0.03794 | S9: =AVERAGE('Ans 1:Ans 40'!E49) -> 0.0365 | T9: =AVERAGE('Ans 1:Ans 40'!F49) -> 0.0363125 | U9: =AVERAGE('Ans 1:Ans 40'!G49) -> 0 | V9: =AVERAGE('Ans 1:Ans 40'!H49) -> 0.040105 | W9: =AVERAGE('Ans 1:Ans 40'!I49) -> 0.037035 | ... AA9: =AVERAGE('Ans 1:Ans 40'!M49) -> 0.038615 | AC9: DRI7 | AD9: =AVERAGE('Ans 1:Ans 40'!B63) -> 0.107955 | AE9: =AVERAGE('Ans 1:Ans 40'!C63) -> 0.1001125 | AF9: =AVERAGE('Ans 1:Ans 40'!D63) -> 0.1035175 | AG9: =AVERAGE('Ans 1:Ans 40'!E63) -> 0.1007125 | AH9: =AVERAGE('Ans 1:Ans 40'!F63) -> 0.1000175 | AI9: =AVERAGE('Ans 1:Ans 40'!G63) -> 0 | AJ9: =AVERAGE('Ans 1:Ans 40'!H63) -> 0.106085 | AK9: =AVERAGE('Ans 1:Ans 40'!I63) -> 0.1041 | ... AO9: =AVERAGE('Ans 1:Ans 40'!M63) -> 0.0992025
A10: DRI9 | B10: =AVERAGE('Ans 1:Ans 40'!B36) -> 0.028415 | C10: =AVERAGE('Ans 1:Ans 40'!C36) -> 0.0280175 | D10: =AVERAGE('Ans 1:Ans 40'!D36) -> 0.0266475 | E10: =AVERAGE('Ans 1:Ans 40'!E36) -> 0.0266475 | F10: =AVERAGE('Ans 1:Ans 40'!F36) -> 0.0280175 | G10: =AVERAGE('Ans 1:Ans 40'!G36) -> 0.0308325 | H10: =AVERAGE('Ans 1:Ans 40'!H36) -> 0 | I10: =AVERAGE('Ans 1:Ans 40'!I36) -> 0.017675 | ... M10: =AVERAGE('Ans 1:Ans 40'!M36) -> 0.02625 | O10: DRI9 | P10: =AVERAGE('Ans 1:Ans 40'!B50) -> 0.06917 | Q10: =AVERAGE('Ans 1:Ans 40'!C50) -> 0.061175 | R10: =AVERAGE('Ans 1:Ans 40'!D50) -> 0.059405 | S10: =AVERAGE('Ans 1:Ans 40'!E50) -> 0.06805 | T10: =AVERAGE('Ans 1:Ans 40'!F50) -> 0.0598675 | U10: =AVERAGE('Ans 1:Ans 40'!G50) -> 0.0654275 | V10: =AVERAGE('Ans 1:Ans 40'!H50) -> 0 | W10: =AVERAGE('Ans 1:Ans 40'!I50) -> 0.064195 | ... AA10: =AVERAGE('Ans 1:Ans 40'!M50) -> 0.0640875 | AC10: DRI9 | AD10: =AVERAGE('Ans 1:Ans 40'!B64) -> 0.12659 | AE10: =AVERAGE('Ans 1:Ans 40'!C64) -> 0.1196975 | AF10: =AVERAGE('Ans 1:Ans 40'!D64) -> 0.1179475 | AG10: =AVERAGE('Ans 1:Ans 40'!E64) -> 0.12496 | AH10: =AVERAGE('Ans 1:Ans 40'!F64) -> 0.11842 | AI10: =AVERAGE('Ans 1:Ans 40'!G64) -> 0.1267275 | AJ10: =AVERAGE('Ans 1:Ans 40'!H64) -> 0 | AK10: =AVERAGE('Ans 1:Ans 40'!I64) -> 0.126015 | ... AO10: =AVERAGE('Ans 1:Ans 40'!M64) -> 0.1213975
A11: DRI10 | B11: =AVERAGE('Ans 1:Ans 40'!B37) -> 0.00707 | C11: =AVERAGE('Ans 1:Ans 40'!C37) -> 0.0017675 | D11: =AVERAGE('Ans 1:Ans 40'!D37) -> 0.0056275 | E11: =AVERAGE('Ans 1:Ans 40'!E37) -> 0.0056275 | F11: =AVERAGE('Ans 1:Ans 40'!F37) -> 0.00386 | G11: =AVERAGE('Ans 1:Ans 40'!G37) -> 0.003535 | H11: =AVERAGE('Ans 1:Ans 40'!H37) -> 0.0017675 | I11: =AVERAGE('Ans 1:Ans 40'!I37) -> 0 | ... M11: =AVERAGE('Ans 1:Ans 40'!M37) -> 0.194175 | O11: DRI10 | P11: =AVERAGE('Ans 1:Ans 40'!B51) -> 0.0372925 | Q11: =AVERAGE('Ans 1:Ans 40'!C51) -> 0.03055 | R11: =AVERAGE('Ans 1:Ans 40'!D51) -> 0.036965 | S11: =AVERAGE('Ans 1:Ans 40'!E51) -> 0.0333575 | T11: =AVERAGE('Ans 1:Ans 40'!F51) -> 0.03545 | U11: =AVERAGE('Ans 1:Ans 40'!G51) -> 0.0419775 | V11: =AVERAGE('Ans 1:Ans 40'!H51) -> 0.026435 | W11: =AVERAGE('Ans 1:Ans 40'!I51) -> 0 | ... AA11: =AVERAGE('Ans 1:Ans 40'!M51) -> 0.28541 | AC11: DRI10 | AD11: =AVERAGE('Ans 1:Ans 40'!B65) -> 0.1015725 | AE11: =AVERAGE('Ans 1:Ans 40'!C65) -> 0.094145 | AF11: =AVERAGE('Ans 1:Ans 40'!D65) -> 0.1000225 | AG11: =AVERAGE('Ans 1:Ans 40'!E65) -> 0.09771 | AH11: =AVERAGE('Ans 1:Ans 40'!F65) -> 0.1001575 | AI11: =AVERAGE('Ans 1:Ans 40'!G65) -> 0.1049775 | AJ11: =AVERAGE('Ans 1:Ans 40'!H65) -> 0.0910475 | AK11: =AVERAGE('Ans 1:Ans 40'!I65) -> 0 | ... AO11: =AVERAGE('Ans 1:Ans 40'!M65) -> 0.344015
A12: DRI11 | B12: =AVERAGE('Ans 1:Ans 40'!B38) -> 0.11036 | C12: =AVERAGE('Ans 1:Ans 40'!C38) -> 0.003535 | D12: =AVERAGE('Ans 1:Ans 40'!D38) -> 0.0017675 | E12: =AVERAGE('Ans 1:Ans 40'!E38) -> 0.004185 | F12: =AVERAGE('Ans 1:Ans 40'!F38) -> 0.0017675 | G12: =AVERAGE('Ans 1:Ans 40'!G38) -> 0.0056275 | H12: =AVERAGE('Ans 1:Ans 40'!H38) -> 0.17643 | I12: =AVERAGE('Ans 1:Ans 40'!I38) -> 0.0020925 | ... M12: =AVERAGE('Ans 1:Ans 40'!M38) -> 0.2224875 | O12: DRI11 | P12: =AVERAGE('Ans 1:Ans 40'!B52) -> 0.191415 | Q12: =AVERAGE('Ans 1:Ans 40'!C52) -> 0.0303575 | R12: =AVERAGE('Ans 1:Ans 40'!D52) -> 0.030155 | S12: =AVERAGE('Ans 1:Ans 40'!E52) -> 0.0377175 | T12: =AVERAGE('Ans 1:Ans 40'!F52) -> 0.0241975 | U12: =AVERAGE('Ans 1:Ans 40'!G52) -> 0.03206 | V12: =AVERAGE('Ans 1:Ans 40'!H52) -> 0.2531 | W12: =AVERAGE('Ans 1:Ans 40'!I52) -> 0.038265 | ... AA12: =AVERAGE('Ans 1:Ans 40'!M52) -> 0.3159875 | AC12: DRI11 | AD12: =AVERAGE('Ans 1:Ans 40'!B66) -> 0.272515 | AE12: =AVERAGE('Ans 1:Ans 40'!C66) -> 0.0918875 | AF12: =AVERAGE('Ans 1:Ans 40'!D66) -> 0.0980875 | AG12: =AVERAGE('Ans 1:Ans 40'!E66) -> 0.0990975 | AH12: =AVERAGE('Ans 1:Ans 40'!F66) -> 0.087935 | AI12: =AVERAGE('Ans 1:Ans 40'!G66) -> 0.0989175 | AJ12: =AVERAGE('Ans 1:Ans 40'!H66) -> 0.300715 | AK12: =AVERAGE('Ans 1:Ans 40'!I66) -> 0.1034075 | ... AO12: =AVERAGE('Ans 1:Ans 40'!M66) -> 0.3739
A13: DRI13 | B13: =AVERAGE('Ans 1:Ans 40'!B39) -> 0.0053025 | C13: =AVERAGE('Ans 1:Ans 40'!C39) -> 0.003535 | D13: =AVERAGE('Ans 1:Ans 40'!D39) -> 0.003535 | E13: =AVERAGE('Ans 1:Ans 40'!E39) -> 0.01093 | F13: =AVERAGE('Ans 1:Ans 40'!F39) -> 0.003535 | G13: =AVERAGE('Ans 1:Ans 40'!G39) -> 0.0059525 | H13: =AVERAGE('Ans 1:Ans 40'!H39) -> 0.003535 | I13: =AVERAGE('Ans 1:Ans 40'!I39) -> 0.0091625 | ... M13: =AVERAGE('Ans 1:Ans 40'!M39) -> 0.004185 | O13: DRI13 | P13: =AVERAGE('Ans 1:Ans 40'!B53) -> 0.031805 | Q13: =AVERAGE('Ans 1:Ans 40'!C53) -> 0.034225 | R13: =AVERAGE('Ans 1:Ans 40'!D53) -> 0.0387975 | S13: =AVERAGE('Ans 1:Ans 40'!E53) -> 0.049125 | T13: =AVERAGE('Ans 1:Ans 40'!F53) -> 0.033865 | U13: =AVERAGE('Ans 1:Ans 40'!G53) -> 0.0395575 | V13: =AVERAGE('Ans 1:Ans 40'!H53) -> 0.0306175 | W13: =AVERAGE('Ans 1:Ans 40'!I53) -> 0.0437025 | ... AA13: =AVERAGE('Ans 1:Ans 40'!M53) -> 0.0275875 | AC13: DRI13 | AD13: =AVERAGE('Ans 1:Ans 40'!B67) -> 0.0922575 | AE13: =AVERAGE('Ans 1:Ans 40'!C67) -> 0.096835 | AF13: =AVERAGE('Ans 1:Ans 40'!D67) -> 0.0994925 | AG13: =AVERAGE('Ans 1:Ans 40'!E67) -> 0.11398 | AH13: =AVERAGE('Ans 1:Ans 40'!F67) -> 0.0985025 | AI13: =AVERAGE('Ans 1:Ans 40'!G67) -> 0.10304 | AJ13: =AVERAGE('Ans 1:Ans 40'!H67) -> 0.094395 | AK13: =AVERAGE('Ans 1:Ans 40'!I67) -> 0.106605 | ... AO13: =AVERAGE('Ans 1:Ans 40'!M67) -> 0.0893775
A14: DRI14 | B14: =AVERAGE('Ans 1:Ans 40'!B40) -> 0.0088375 | C14: =AVERAGE('Ans 1:Ans 40'!C40) -> 0.003535 | D14: =AVERAGE('Ans 1:Ans 40'!D40) -> 0.007395 | E14: =AVERAGE('Ans 1:Ans 40'!E40) -> 0.0053025 | F14: =AVERAGE('Ans 1:Ans 40'!F40) -> 0.003535 | G14: =AVERAGE('Ans 1:Ans 40'!G40) -> 0.003535 | H14: =AVERAGE('Ans 1:Ans 40'!H40) -> 0.0053025 | I14: =AVERAGE('Ans 1:Ans 40'!I40) -> 0.0053025 | ... M14: =AVERAGE('Ans 1:Ans 40'!M40) -> 0.2301675 | O14: DRI14 | P14: =AVERAGE('Ans 1:Ans 40'!B54) -> 0.0368525 | Q14: =AVERAGE('Ans 1:Ans 40'!C54) -> 0.029965 | R14: =AVERAGE('Ans 1:Ans 40'!D54) -> 0.0407525 | S14: =AVERAGE('Ans 1:Ans 40'!E54) -> 0.033505 | T14: =AVERAGE('Ans 1:Ans 40'!F54) -> 0.030645 | U14: =AVERAGE('Ans 1:Ans 40'!G54) -> 0.0390175 | V14: =AVERAGE('Ans 1:Ans 40'!H54) -> 0.03371 | W14: =AVERAGE('Ans 1:Ans 40'!I54) -> 0.032705 | ... AA14: =AVERAGE('Ans 1:Ans 40'!M54) -> 0.321575 | AC14: DRI14 | AD14: =AVERAGE('Ans 1:Ans 40'!B68) -> 0.097375 | AE14: =AVERAGE('Ans 1:Ans 40'!C68) -> 0.0886375 | AF14: =AVERAGE('Ans 1:Ans 40'!D68) -> 0.1069475 | AG14: =AVERAGE('Ans 1:Ans 40'!E68) -> 0.0988025 | AH14: =AVERAGE('Ans 1:Ans 40'!F68) -> 0.092875 | AI14: =AVERAGE('Ans 1:Ans 40'!G68) -> 0.100735 | AJ14: =AVERAGE('Ans 1:Ans 40'!H68) -> 0.09369 | AK14: =AVERAGE('Ans 1:Ans 40'!I68) -> 0.0924925 | ... AO14: =AVERAGE('Ans 1:Ans 40'!M68) -> 0.3673
A15: DRI15 | B15: =AVERAGE('Ans 1:Ans 40'!B41) -> 0.00707 | C15: =AVERAGE('Ans 1:Ans 40'!C41) -> 0.003535 | D15: =AVERAGE('Ans 1:Ans 40'!D41) -> 0.007395 | E15: =AVERAGE('Ans 1:Ans 40'!E41) -> 0.0130225 | F15: =AVERAGE('Ans 1:Ans 40'!F41) -> 0.01093 | G15: =AVERAGE('Ans 1:Ans 40'!G41) -> 0.0091625 | H15: =AVERAGE('Ans 1:Ans 40'!H41) -> 0.0056275 | I15: =AVERAGE('Ans 1:Ans 40'!I41) -> 0.0099525 | ... M15: =AVERAGE('Ans 1:Ans 40'!M41) -> 0 | O15: DRI15 | P15: =AVERAGE('Ans 1:Ans 40'!B55) -> 0.045105 | Q15: =AVERAGE('Ans 1:Ans 40'!C55) -> 0.03934 | R15: =AVERAGE('Ans 1:Ans 40'!D55) -> 0.0347325 | S15: =AVERAGE('Ans 1:Ans 40'!E55) -> 0.045865 | T15: =AVERAGE('Ans 1:Ans 40'!F55) -> 0.04515 | U15: =AVERAGE('Ans 1:Ans 40'!G55) -> 0.0351475 | V15: =AVERAGE('Ans 1:Ans 40'!H55) -> 0.035665 | W15: =AVERAGE('Ans 1:Ans 40'!I55) -> 0.041935 | ... AA15: =AVERAGE('Ans 1:Ans 40'!M55) -> 0 | AC15: DRI15 | AD15: =AVERAGE('Ans 1:Ans 40'!B69) -> 0.1053 | AE15: =AVERAGE('Ans 1:Ans 40'!C69) -> 0.1049525 | AF15: =AVERAGE('Ans 1:Ans 40'!D69) -> 0.0979675 | AG15: =AVERAGE('Ans 1:Ans 40'!E69) -> 0.10899 | AH15: =AVERAGE('Ans 1:Ans 40'!F69) -> 0.1105575 | AI15: =AVERAGE('Ans 1:Ans 40'!G69) -> 0.0960625 | AJ15: =AVERAGE('Ans 1:Ans 40'!H69) -> 0.09644 | AK15: =AVERAGE('Ans 1:Ans 40'!I69) -> 0.1073325 | ... AO15: =AVERAGE('Ans 1:Ans 40'!M69) -> 0
A17: Ma trận quan hệ trực tiếp dạng số thực DF
B19: DRI1 | C19: DRI3 | D19: DRI4 | E19: DRI5 | F19: DRI6 | G19: DRI7 | H19: DRI9 | I19: DRI10 | J19: DRI11 | K19: DRI13 | L19: DRI14 | M19: DRI15 | N19: Tổng
A20: DRI1 | B20: =(B4+(P4*P4)+AD4)/74 -> 0 | C20: =(C4+(Q4*Q4)+AE4)/74 -> 0.0076348781 | D20: =(D4+(R4*R4)+AF4)/74 -> 0.0076368729 | E20: =(E4+(S4*S4)+AG4)/74 -> 0.0026981777 | F20: =(F4+(T4*T4)+AH4)/74 -> 0.0039511183 | G20: =(G4+(U4*U4)+AI4)/74 -> 0.0024707297 | H20: =(H4+(V4*V4)+AJ4)/74 -> 0.0030619028 | I20: =(I4+(W4*W4)+AK4)/74 -> 0.0022910177 | ... M20: =(M4+(AA4*AA4)+AO4)/74 -> 0.002852237 | N20: =SUM(B20:M20) -> 0.045916465
A21: DRI3 | B21: =(B5+(P5*P5)+AD5)/74 -> 0.00262067 | C21: =(C5+(Q5*Q5)+AE5)/74 -> 0 | D21: =(D5+(R5*R5)+AF5)/74 -> 0.010045244 | E21: =(E5+(S5*S5)+AG5)/74 -> 0.0087362958 | F21: =(F5+(T5*T5)+AH5)/74 -> 0.0037232607 | G21: =(G5+(U5*U5)+AI5)/74 -> 0.0066589654 | H21: =(H5+(V5*V5)+AJ5)/74 -> 0.0067353117 | I21: =(I5+(W5*W5)+AK5)/74 -> 0.0020437546 | ... M21: =(M5+(AA5*AA5)+AO5)/74 -> 0.0090251835 | N21: =SUM(B21:M21) -> 0.073799163
A22: DRI4 | B22: =(B6+(P6*P6)+AD6)/74 -> 0.0039021216 | C22: =(C6+(Q6*Q6)+AE6)/74 -> 0.0012817437 | D22: =(D6+(R6*R6)+AF6)/74 -> 0 | E22: =(E6+(S6*S6)+AG6)/74 -> 0.0040204737 | F22: =(F6+(T6*T6)+AH6)/74 -> 0.0014958424 | G22: =(G6+(U6*U6)+AI6)/74 -> 0.0038874294 | H22: =(H6+(V6*V6)+AJ6)/74 -> 0.0041888557 | I22: =(I6+(W6*W6)+AK6)/74 -> 0.0017387106 | ... M22: =(M6+(AA6*AA6)+AO6)/74 -> 0.0093415369 | N22: =SUM(B22:M22) -> 0.058316792
A23: DRI5 | B23: =(B7+(P7*P7)+AD7)/74 -> 0.0036731293 | C23: =(C7+(Q7*Q7)+AE7)/74 -> 0.0037990752 | D23: =(D7+(R7*R7)+AF7)/74 -> 0.003696885 | E23: =(E7+(S7*S7)+AG7)/74 -> 0 | F23: =(F7+(T7*T7)+AH7)/74 -> 0.0039253412 | G23: =(G7+(U7*U7)+AI7)/74 -> 0.0040218047 | H23: =(H7+(V7*V7)+AJ7)/74 -> 0.00854562 | I23: =(I7+(W7*W7)+AK7)/74 -> 0.0033548403 | ... M23: =(M7+(AA7*AA7)+AO7)/74 -> 0.0064522482 | N23: =SUM(B23:M23) -> 0.058735419
A24: DRI6 | B24: =(B8+(P8*P8)+AD8)/74 -> 0.00136731 | C24: =(C8+(Q8*Q8)+AE8)/74 -> 0.0016478931 | D24: =(D8+(R8*R8)+AF8)/74 -> 0.0013312477 | E24: =(E8+(S8*S8)+AG8)/74 -> 0.0013901512 | F24: =(F8+(T8*T8)+AH8)/74 -> 0 | G24: =(G8+(U8*U8)+AI8)/74 -> 0.0076559737 | H24: =(H8+(V8*V8)+AJ8)/74 -> 0.0017402624 | I24: =(I8+(W8*W8)+AK8)/74 -> 0.0017991774 | ... M24: =(M8+(AA8*AA8)+AO8)/74 -> 0.0016443029 | N24: =SUM(B24:M24) -> 0.038319636
A25: DRI7 | B25: =(B9+(P9*P9)+AD9)/74 -> 0.0015825989 | C25: =(C9+(Q9*Q9)+AE9)/74 -> 0.0014680028 | D25: =(D9+(R9*R9)+AF9)/74 -> 0.0014661073 | E25: =(E9+(S9*S9)+AG9)/74 -> 0.0014745236 | F25: =(F9+(T9*T9)+AH9)/74 -> 0.0014410621 | G25: =(G9+(U9*U9)+AI9)/74 -> 0 | H25: =(H9+(V9*V9)+AJ9)/74 -> 0.0015313637 | I25: =(I9+(W9*W9)+AK9)/74 -> 0.0015491093 | ... M25: =(M9+(AA9*AA9)+AO9)/74 -> 0.00143238 | N25: =SUM(B25:M25) -> 0.022120307
A26: DRI9 | B26: =(B10+(P10*P10)+AD10)/74 -> 0.0021593174 | C26: =(C10+(Q10*Q10)+AE10)/74 -> 0.0020467214 | D26: =(D10+(R10*R10)+AF10)/74 -> 0.0020016751 | E26: =(E10+(S10*S10)+AG10)/74 -> 0.0021113284 | F26: =(F10+(T10*T10)+AH10)/74 -> 0.0020273192 | G26: =(G10+(U10*U10)+AI10)/74 -> 0.0021870373 | H26: =(H10+(V10*V10)+AJ10)/74 -> 0 | I26: =(I10+(W10*W10)+AK10)/74 -> 0.0019974459 | ... M26: =(M10+(AA10*AA10)+AO10)/74 -> 0.0020507393 | N26: =SUM(B26:M26) -> 0.023615106
A27: DRI10 | B27: =(B11+(P11*P11)+AD11)/74 -> 0.0014869355 | C27: =(C11+(Q11*Q11)+AE11)/74 -> 0.0013087271 | D27: =(D11+(R11*R11)+AF11)/74 -> 0.0014461677 | E27: =(E11+(S11*S11)+AG11)/74 -> 0.0014114895 | F27: =(F11+(T11*T11)+AH11)/74 -> 0.0014226244 | G27: =(G11+(U11*U11)+AI11)/74 -> 0.0014901974 | H27: =(H11+(V11*V11)+AJ11)/74 -> 0.0012637001 | I27: =(I11+(W11*W11)+AK11)/74 -> 0 | ... M27: =(M11+(AA11*AA11)+AO11)/74 -> 0.0083736334 | N27: =SUM(B27:M27) -> 0.042681052
A28: DRI11 | B28: =(B12+(P12*P12)+AD12)/74 -> 0.0056691176 | C28: =(C12+(Q12*Q12)+AE12)/74 -> 0.001301947 | D28: =(D12+(R12*R12)+AF12)/74 -> 0.0013616801 | E28: =(E12+(S12*S12)+AG12)/74 -> 0.0014149339 | F28: =(F12+(T12*T12)+AH12)/74 -> 0.0012201084 | G28: =(G12+(U12*U12)+AI12)/74 -> 0.00142666 | H28: =(H12+(V12*V12)+AJ12)/74 -> 0.0073135758 | I28: =(I12+(W12*W12)+AK12)/74 -> 0.0014454623 | ... M28: =(M12+(AA12*AA12)+AO12)/74 -> 0.0094085892 | N28: =SUM(B28:M28) -> 0.0495311
A29: DRI13 | B29: =(B13+(P13*P13)+AD13)/74 -> 0.0013320481 | C29: =(C13+(Q13*Q13)+AE13)/74 -> 0.0013721804 | D29: =(D13+(R13*R13)+AF13)/74 -> 0.0014126047 | E29: =(E13+(S13*S13)+AG13)/74 -> 0.0017205847 | F29: =(F13+(T13*T13)+AH13)/74 -> 0.0013943829 | G29: =(G13+(U13*U13)+AI13)/74 -> 0.0014940175 | H29: =(H13+(V13*V13)+AJ13)/74 -> 0.0013360464 | I29: =(I13+(W13*W13)+AK13)/74 -> 0.0015902353 | ... M29: =(M13+(AA13*AA13)+AO13)/74 -> 0.0012746428 | N29: =SUM(B29:M29) -> 0.015968571
A30: DRI14 | B30: =(B14+(P14*P14)+AD14)/74 -> 0.0014536568 | C30: =(C14+(Q14*Q14)+AE14)/74 -> 0.0012577081 | D30: =(D14+(R14*R14)+AF14)/74 -> 0.0015676117 | E30: =(E14+(S14*S14)+AG14)/74 -> 0.0014219944 | F30: =(F14+(T14*T14)+AH14)/74 -> 0.0013155286 | G30: =(G14+(U14*U14)+AI14)/74 -> 0.0014296266 | H30: =(H14+(V14*V14)+AJ14)/74 -> 0.0013530928 | I30: =(I14+(W14*W14)+AK14)/74 -> 0.0013360083 | ... M30: =(M14+(AA14*AA14)+AO14)/74 -> 0.0094713241 | N30: =SUM(B30:M30) -> 0.023411212
A31: DRI15 | B31: =(B15+(P15*P15)+AD15)/74 -> 0.0015460062 | C31: =(C15+(Q15*Q15)+AE15)/74 -> 0.0014869613 | D31: =(D15+(R15*R15)+AF15)/74 -> 0.0014401195 | E31: =(E15+(S15*S15)+AG15)/74 -> 0.0016772446 | F31: =(F15+(T15*T15)+AH15)/74 -> 0.0016692706 | G31: =(G15+(U15*U15)+AI15)/74 -> 0.0014386533 | H31: =(H15+(V15*V15)+AJ15)/74 -> 0.0013964796 | I31: =(I15+(W15*W15)+AK15)/74 -> 0.0016086965 | ... M31: =(M15+(AA15*AA15)+AO15)/74 -> 0 | N31: =SUM(B31:M31) -> 0.017258562
A32: Tổng | B32: =SUM(B20:B31) -> 0.026792912 | C32: =SUM(C20:C31) -> 0.024605838 | D32: =SUM(D20:D31) -> 0.033406215 | E32: =SUM(E20:E31) -> 0.028077197 | F32: =SUM(F20:F31) -> 0.023585859 | G32: =SUM(G20:G31) -> 0.034161095 | H32: =SUM(H20:H31) -> 0.038466211 | I32: =SUM(I20:I31) -> 0.020754458 | ... M32: =SUM(M20:M31) -> 0.061326817 | N32: Hệ số chuẩn hóa
N33: =MAX(B32:M32,N20:N31) -> 0.073799163
A34: Ma trận chuẩn hóa NDF | P34: Ma trận đơn vị (I) | AC34: I-NDF
AP35: Ngịch đảo (I-NDF)
B36: DRI1 | C36: DRI3 | D36: DRI4 | E36: DRI5 | F36: DRI6 | G36: DRI7 | H36: DRI9 | I36: DRI10 | J36: DRI11 | K36: DRI13 | L36: DRI14 | M36: DRI15
A37: DRI1 | B37: =B20/$N$33 -> 0 | C37: =C20/$N$33 -> 0.10345481 | D37: =D20/$N$33 -> 0.10348184 | E37: =E20/$N$33 -> 0.036561087 | F37: =F20/$N$33 -> 0.053538795 | G37: =G20/$N$33 -> 0.033479101 | H37: =H20/$N$33 -> 0.041489668 | I37: =I20/$N$33 -> 0.031043952 | ... M37: =M20/$N$33 -> 0.038648636 | P37: 1 | Q37: 0 | R37: 0 | S37: 0 | T37: 0 | U37: 0 | V37: 0 | W37: 0 | X37: 0 | Y37: 0 | Z37: 0 | AA37: 0 | AC37: =P37-B37 -> 1 | AD37: =Q37-C37 -> -0.10345481 | AE37: =R37-D37 -> -0.10348184 | AF37: =S37-E37 -> -0.036561087 | AG37: =T37-F37 -> -0.053538795 | AH37: =U37-G37 -> -0.033479101 | AI37: =V37-H37 -> -0.041489668 | AJ37: =W37-I37 -> -0.031043952 | ... AN37: =AA37-M37 -> -0.038648636 | AP37: {=MINVERSE(AC37:AN48)} -> 1.0472452 | AQ37: 0.13359663 | AR37: 0.14943218 | AS37: 0.082109625 | AT37: 0.086993542 | AU37: 0.084391263 | AV37: 0.10518883 | AW37: 0.062123333 | AX37: 0.19611721 | AY37: 0.13116882 | AZ37: 0.12227863 | BA37: 0.13941622
A38: DRI3 | B38: =B21/$N$33 -> 0.035510837 | C38: =C21/$N$33 -> 0 | D38: =D21/$N$33 -> 0.13611596 | E38: =E21/$N$33 -> 0.11837933 | F38: =F21/$N$33 -> 0.050451259 | G38: =G21/$N$33 -> 0.090230907 | H38: =H21/$N$33 -> 0.09126542 | I38: =I21/$N$33 -> 0.027693465 | ... M38: =M21/$N$33 -> 0.12229385 | P38: 0 | Q38: 1 | R38: 0 | S38: 0 | T38: 0 | U38: 0 | V38: 0 | W38: 0 | X38: 0 | Y38: 0 | Z38: 0 | AA38: 0 | AC38: =P38-B38 -> -0.035510837 | AD38: =Q38-C38 -> 1 | AE38: =R38-D38 -> -0.13611596 | AF38: =S38-E38 -> -0.11837933 | AG38: =T38-F38 -> -0.050451259 | AH38: =U38-G38 -> -0.090230907 | AI38: =V38-H38 -> -0.09126542 | AJ38: =W38-I38 -> -0.027693465 | ... AN38: =AA38-M38 -> -0.12229385 | AP38: 0.096793234 | AQ38: 1.049881 | AR38: 0.18985924 | AS38: 0.16856446 | AT38: 0.097304569 | AU38: 0.15153324 | AV38: 0.1702699 | AW38: 0.072831755 | AX38: 0.20781139 | AY38: 0.25095248 | AZ38: 0.20021676 | BA38: 0.2455332
A39: DRI4 | B39: =B22/$N$33 -> 0.052874875 | C39: =C22/$N$33 -> 0.017367998 | D39: =D22/$N$33 -> 0 | E39: =E22/$N$33 -> 0.054478581 | F39: =F22/$N$33 -> 0.020269097 | G39: =G22/$N$33 -> 0.052675792 | H39: =H22/$N$33 -> 0.056760206 | I39: =I22/$N$33 -> 0.023560031 | ... M39: =M22/$N$33 -> 0.12658053 | P39: 0 | Q39: 0 | R39: 1 | S39: 0 | T39: 0 | U39: 0 | V39: 0 | W39: 0 | X39: 0 | Y39: 0 | Z39: 0 | AA39: 0 | AC39: =P39-B39 -> -0.052874875 | AD39: =Q39-C39 -> -0.017367998 | AE39: =R39-D39 -> 1 | AF39: =S39-E39 -> -0.054478581 | AG39: =T39-F39 -> -0.020269097 | AH39: =U39-G39 -> -0.052675792 | AI39: =V39-H39 -> -0.056760206 | AJ39: =W39-I39 -> -0.023560031 | ... AN39: =AA39-M39 -> -0.12658053 | AP39: 0.097228539 | AQ39: 0.055443228 | AR39: 1.0454243 | AS39: 0.091870767 | AT39: 0.055871555 | AU39: 0.094843447 | AV39: 0.11504353 | AW39: 0.056590121 | AX39: 0.20478778 | AY39: 0.21680186 | AZ39: 0.18483726 | BA39: 0.21717889
A40: DRI5 | B40: =B23/$N$33 -> 0.049771964 | C40: =C23/$N$33 -> 0.051478567 | D40: =D23/$N$33 -> 0.05009386 | E40: =E23/$N$33 -> 0 | F40: =F23/$N$33 -> 0.053189508 | G40: =G23/$N$33 -> 0.054496617 | H40: =H23/$N$33 -> 0.11579562 | I40: =I23/$N$33 -> 0.045459057 | ... M40: =M23/$N$33 -> 0.087429828 | P40: 0 | Q40: 0 | R40: 0 | S40: 1 | T40: 0 | U40: 0 | V40: 0 | W40: 0 | X40: 0 | Y40: 0 | Z40: 0 | AA40: 0 | AC40: =P40-B40 -> -0.049771964 | AD40: =Q40-C40 -> -0.051478567 | AE40: =R40-D40 -> -0.05009386 | AF40: =S40-E40 -> 1 | AG40: =T40-F40 -> -0.053189508 | AH40: =U40-G40 -> -0.054496617 | AI40: =V40-H40 -> -0.11579562 | AJ40: =W40-I40 -> -0.045459057 | ... AN40: =AA40-M40 -> -0.087429828 | AP40: 0.097427538 | AQ40: 0.089450356 | AR40: 0.099067881 | AS40: 1.0452706 | AT40: 0.089651237 | AU40: 0.10403379 | AV40: 0.17485134 | AW40: 0.079317272 | AX40: 0.20731594 | AY40: 0.1425363 | AZ40: 0.1973672 | BA40: 0.19073013
A41: DRI6 | B41: =B24/$N$33 -> 0.018527446 | C41: =C24/$N$33 -> 0.022329428 | D41: =D24/$N$33 -> 0.018038792 | E41: =E24/$N$33 -> 0.01883695 | F41: =F24/$N$33 -> 0 | G41: =G24/$N$33 -> 0.10374066 | H41: =H24/$N$33 -> 0.023581058 | I41: =I24/$N$33 -> 0.024379374 | ... M41: =M24/$N$33 -> 0.022280779 | P41: 0 | Q41: 0 | R41: 0 | S41: 0 | T41: 1 | U41: 0 | V41: 0 | W41: 0 | X41: 0 | Y41: 0 | Z41: 0 | AA41: 0 | AC41: =P41-B41 -> -0.018527446 | AD41: =Q41-C41 -> -0.022329428 | AE41: =R41-D41 -> -0.018038792 | AF41: =S41-E41 -> -0.01883695 | AG41: =T41-F41 -> 1 | AH41: =U41-G41 -> -0.10374066 | AI41: =V41-H41 -> -0.023581058 | AJ41: =W41-I41 -> -0.024379374 | ... AN41: =AA41-M41 -> -0.022280779 | AP41: 0.050635126 | AQ41: 0.04583704 | AR41: 0.047356022 | AS41: 0.04535954 | AT41: 1.0231328 | AU41: 0.12989763 | AV41: 0.065045121 | AW41: 0.045927896 | AX41: 0.17076224 | AY41: 0.1796199 | AZ41: 0.078190666 | BA41: 0.084766396
A42: DRI7 | B42: =B25/$N$33 -> 0.021444673 | C42: =C25/$N$33 -> 0.019891862 | D42: =D25/$N$33 -> 0.019866178 | E42: =E25/$N$33 -> 0.019980222 | F42: =F25/$N$33 -> 0.019526808 | G42: =G25/$N$33 -> 0 | H42: =H25/$N$33 -> 0.02075042 | I42: =I25/$N$33 -> 0.020990879 | ... M42: =M25/$N$33 -> 0.019409163 | P42: 0 | Q42: 0 | R42: 0 | S42: 0 | T42: 0 | U42: 1 | V42: 0 | W42: 0 | X42: 0 | Y42: 0 | Z42: 0 | AA42: 0 | AC42: =P42-B42 -> -0.021444673 | AD42: =Q42-C42 -> -0.019891862 | AE42: =R42-D42 -> -0.019866178 | AF42: =S42-E42 -> -0.019980222 | AG42: =T42-F42 -> -0.019526808 | AH42: =U42-G42 -> 1 | AI42: =V42-H42 -> -0.02075042 | AJ42: =W42-I42 -> -0.020990879 | ... AN42: =AA42-M42 -> -0.019409163 | AP42: 0.044145484 | AQ42: 0.036279509 | AR42: 0.040664337 | AS42: 0.03804425 | AT42: 0.035054288 | AU42: 1.0211658 | AV42: 0.051322859 | AW42: 0.035268165 | AX42: 0.13480278 | AY42: 0.064260465 | AZ42: 0.058218271 | BA42: 0.066412784
A43: DRI9 | B43: =B26/$N$33 -> 0.029259375 | C43: =C26/$N$33 -> 0.027733666 | D43: =D26/$N$33 -> 0.027123276 | E43: =E26/$N$33 -> 0.02860911 | F43: =F26/$N$33 -> 0.027470761 | G43: =G26/$N$33 -> 0.029634987 | H43: =H26/$N$33 -> 0 | I43: =I26/$N$33 -> 0.02706597 | ... M43: =M26/$N$33 -> 0.02778811 | P43: 0 | Q43: 0 | R43: 0 | S43: 0 | T43: 0 | U43: 0 | V43: 1 | W43: 0 | X43: 0 | Y43: 0 | Z43: 0 | AA43: 0 | AC43: =P43-B43 -> -0.029259375 | AD43: =Q43-C43 -> -0.027733666 | AE43: =R43-D43 -> -0.027123276 | AF43: =S43-E43 -> -0.02860911 | AG43: =T43-F43 -> -0.027470761 | AH43: =U43-G43 -> -0.029634987 | AI43: =V43-H43 -> 1 | AJ43: =W43-I43 -> -0.02706597 | ... AN43: =AA43-M43 -> -0.02778811 | AP43: 0.049003711 | AQ43: 0.04498435 | AR43: 0.049764054 | AS43: 0.048040057 | AT43: 0.044003822 | AU43: 0.052468911 | AV43: 1.0281779 | AW43: 0.04198256 | AX43: 0.068260031 | AY43: 0.083197316 | AZ43: 0.064371208 | BA43: 0.071628748
...

Sheet Thang đánh giá
A1: F | B1: R | C1: F:R | D1: Z-Fuzzy
A2: AI | B2: VH | C2: AI;VH | D2: (0,2846; 0,3795; 0,3795)
A3: AI | B3: H | C3: AI;H | D3: (0,251; 0,3347; 0,3347)
A4: VI | B4: VH | C4: VI;VH | D4: (0,1897; 0,2846; 0,3795)
A5: AI | B5: M | C5: AI;M | D5: (0,2121; 0,2828; 0,2828)
A6: VI | B6: H | C6: VI;H | D6: (0,1673; 0,251; 0,3347)
A7: VI | B7: M | C7: VI;M | D7: (0,1414; 0,2121; 0,2828)
A8: AI | B8: L | C8: AI;L | D8: (0,1643; 0,2191; 0,2191)
A9: FI | B9: VH | C9: FI;VH | D9: (0,0949; 0,1897; 0,2846)
A10: FI | B10: H | C10: FI;H | D10: (0,0837; 0,1673; 0,251)
A11: VI | B11: L | C11: VI;L | D11: (0,1095; 0,1643; 0,2191)
A12: FI | B12: M | C12: FI;M | D12: (0,0707; 0,1414; 0,2121)
... A26: NI | B26: VL | C26: NI;VL | D26: (0; 0; 0,0316)
C27: 0 | D27: (0; 0; 0)

Sheet Ans 1
B1: DRI1 | C1: DRI3 | D1: DRI4 | E1: DRI5 | F1: DRI6 | G1: DRI7 | H1: DRI9 | I1: DRI10 | J1: DRI11 | K1: DRI13 | L1: DRI14 | M1: DRI15
A2: DRI1 | B2: 0 | C2: VI;H | D2: VI;VH | E2: FI;H | F2: WI;M | G2: NI;L | H2: NI;M | I2: NI;M | J2: VI;H | K2: NI;L | L2: NI;M | M2: WI;L
A3: DRI3 | B3: WI;M | C3: 0 | D3: AI;VH | E3: AI;VH | F3: NI;M | G3: WI;M | H3: VI;VH | I3: NI;M | J3: VI;H | K3: AI;H | L3: AI;VH | M3: VI;VH
A4: DRI4 | B4: WI;M | C4: WI;M | D4: 0 | E4: VI;M | F4: WI;M | G4: FI;H | H4: WI;L | I4: WI;L | J4: AI;VH | K4: AI;VH | L4: VI;VH | M4: AI;VH
A5: DRI5 | B5: FI;M | C5: NI;H | D5: WI;L | E5: 0 | F5: VI;H | G5: WI;M | H5: VI;VH | I5: NI;M | J5: AI;VH | K5: WI;M | L5: VI;VH | M5: AI;VH
A6: DRI6 | B6: NI;M | C6: WI;VL | D6: NI;L | E6: WI;M | F6: 0 | G6: FI;H | H6: NI;M | I6: NI;L | J6: VI;H | K6: AI;H | L6: NI;H | M6: WI;M
A7: DRI7 | B7: WI;M | C7: NI;L | D7: WI;L | E7: NI;M | F7: NI;M | G7: 0 | H7: WI;M | I7: NI;M | J7: AI;VH | K7: NI;VL | L7: NI;VL | M7: WI;VL
A8: DRI9 | B8: NI;M | C8: NI;L | D8: WI;L | E8: NI;VL | F8: FI;M | G8: FI;M | H8: 0 | I8: WI;M | J8: FI;M | K8: NI;L | L8: NI;L | M8: FI;M
A9: DRI10 | B9: WI;H | C9: NI;M | D9: WI;M | E9: NI;M | F9: WI;L | G9: WI;L | H9: WI;M | I9: 0 | J9: AI;VH | K9: AI;VH | L9: VI;H | M9: VI;VH
A10: DRI11 | B10: VI;H | C10: WI;L | D10: WI;L | E10: WI;M | F10: NI;L | G10: NI;M | H10: VI;H | I10: NI;M | J10: 0 | K10: AI;H | L10: VI;H | M10: AI;VH
A11: DRI13 | B11: WI;M | C11: WI;H | D11: WI;L | E11: WI;M | F11: FI;M | G11: WI;L | H11: NI;L | I11: WI;L | J11: NI;M | K11: 0 | L11: NI;M | M11: WI;L
A12: DRI14 | B12: NI;M | C12: WI;M | D12: NI;VL | E12: NI;M | F12: NI;M | G12: NI;H | H12: WI;L | I12: NI;M | J12: WI;L | K12: NI;M | L12: 0 | M12: VI;VH
A13: DRI15 | B13: NI;L | C13: WI;H | D13: NI;M | E13: FI;M | F13: NI;L | G13: NI;M | H13: NI;VL | I13: WI;L | J13: NI;M | K13: FI;H | L13: WI;L | M13: 0
B15: DRI1 | C15: DRI3 | D15: DRI4 | E15: DRI5 | F15: DRI6 | G15: DRI7 | H15: DRI9 | I15: DRI10 | J15: DRI11 | K15: DRI13 | L15: DRI14 | M15: DRI15
A16: DRI1 | B16: =VLOOKUP(B2,'Thang đánh giá'!$C$2:$D$27,2,FALSE) -> (0; 0; 0) | C16: =VLOOKUP(C2,'Thang đánh giá'!$C$2:$D$27,2,FALSE) -> (0,1673; 0,251; 0,3347) | D16: =VLOOKUP(D2,'Thang đánh giá'!$C$2:$D$27,2,FALSE) -> (0,1897; 0,2846; 0,3795) | E16: =VLOOKUP(E2,'Thang đánh giá'!$C$2:$D$27,2,FALSE) -> (0,0837; 0,1673; 0,251) | F16: =VLOOKUP(F2,'Thang đánh giá'!$C$2:$D$27,2,FALSE) -> (0; 0,0707; 0,1414) | G16: =VLOOKUP(G2,'Thang đánh giá'!$C$2:$D$27,2,FALSE) -> (0; 0; 0,0548) | H16: =VLOOKUP(H2,'Thang đánh giá'!$C$2:$D$27,2,FALSE) -> (0; 0; 0,0707) | I16: =VLOOKUP(I2,'Thang đánh giá'!$C$2:$D$27,2,FALSE) -> (0; 0; 0,0707) | ... M16: =VLOOKUP(M2,'Thang đánh giá'!$C$2:$D$27,2,FALSE) -> (0; 0,0548; 0,1095)
A17: DRI3 | B17: =VLOOKUP(B3,'Thang đánh giá'!$C$2:$D$27,2,FALSE) -> (0; 0,0707; 0,1414) | C17: =VLOOKUP(C3,'Thang đánh giá'!$C$2:$D$27,2,FALSE) -> (0; 0; 0) | D17: =VLOOKUP(D3,'Thang đánh giá'!$C$2:$D$27,2,FALSE) -> (0,2846; 0,3795; 0,3795) | E17: =VLOOKUP(E3,'Thang đánh giá'!$C$2:$D$27,2,FALSE) -> (0,2846; 0,3795; 0,3795) | F17: =VLOOKUP(F3,'Thang đánh giá'!$C$2:$D$27,2,FALSE) -> (0; 0; 0,0707) | G17: =VLOOKUP(G3,'Thang đánh giá'!$C$2:$D$27,2,FALSE) -> (0; 0,0707; 0,1414) | H17: =VLOOKUP(H3,'Thang đánh giá'!$C$2:$D$27,2,FALSE) -> (0,1897; 0,2846; 0,3795) | I17: =VLOOKUP(I3,'Thang đánh giá'!$C$2:$D$27,2,FALSE) -> (0; 0; 0,0707) | ... M17: =VLOOKUP(M3,'Thang đánh giá'!$C$2:$D$27,2,FALSE) -> (0,1897; 0,2846; 0,3795)
A18: DRI4 | B18: =VLOOKUP(B4,'Thang đánh giá'!$C$2:$D$27,2,FALSE) -> (0; 0,0707; 0,1414) | C18: =VLOOKUP(C4,'Thang đánh giá'!$C$2:$D$27,2,FALSE) -> (0; 0,0707; 0,1414) | D18: =VLOOKUP(D4,'Thang đánh giá'!$C$2:$D$27,2,FALSE) -> (0; 0; 0) | E18: =VLOOKUP(E4,'Thang đánh giá'!$C$2:$D$27,2,FALSE) -> (0,1414; 0,2121; 0,2828) | F18: =VLOOKUP(F4,'Thang đánh giá'!$C$2:$D$27,2,FALSE) -> (0; 0,0707; 0,1414) | G18: =VLOOKUP(G4,'Thang đánh giá'!$C$2:$D$27,2,FALSE) -> (0,0837; 0,1673; 0,251) | H18: =VLOOKUP(H4,'Thang đánh giá'!$C$2:$D$27,2,FALSE) -> (0; 0,0548; 0,1095) | I18: =VLOOKUP(I4,'Thang đánh giá'!$C$2:$D$27,2,FALSE) -> (0; 0,0548; 0,1095) | ... M18: =VLOOKUP(M4,'Thang đánh giá'!$C$2:$D$27,2,FALSE) -> (0,2846; 0,3795; 0,3795)
A19: DRI5 | B19: =VLOOKUP(B5,'Thang đánh giá'!$C$2:$D$27,2,FALSE) -> (0,0707; 0,1414; 0,2121) | C19: =VLOOKUP(C5,'Thang đánh giá'!$C$2:$D$27,2,FALSE) -> (0; 0; 0,0837) | D19: =VLOOKUP(D5,'Thang đánh giá'!$C$2:$D$27,2,FALSE) -> (0; 0,0548; 0,1095) | E19: =VLOOKUP(E5,'Thang đánh giá'!$C$2:$D$27,2,FALSE) -> (0; 0; 0) | F19: =VLOOKUP(F5,'Thang đánh giá'!$C$2:$D$27,2,FALSE) -> (0,1673; 0,251; 0,3347) | G19: =VLOOKUP(G5,'Thang đánh giá'!$C$2:$D$27,2,FALSE) -> (0; 0,0707; 0,1414) | H19: =VLOOKUP(H5,'Thang đánh giá'!$C$2:$D$27,2,FALSE) -> (0,1897; 0,2846; 0,3795) | I19: =VLOOKUP(I5,'Thang đánh giá'!$C$2:$D$27,2,FALSE) -> (0; 0; 0,0707) | ... M19: =VLOOKUP(M5,'Thang đánh giá'!$C$2:$D$27,2,FALSE) -> (0,2846; 0,3795; 0,3795)
A20: DRI6 | B20: =VLOOKUP(B6,'Thang đánh giá'!$C$2:$D$27,2,FALSE) -> (0; 0; 0,0707) | C20: =VLOOKUP(C6,'Thang đánh giá'!$C$2:$D$27,2,FALSE) -> (0; 0,0316; 0,0632) | D20: =VLOOKUP(D6,'Thang đánh giá'!$C$2:$D$27,2,FALSE) -> (0; 0; 0,0548) | E20: =VLOOKUP(E6,'Thang đánh giá'!$C$2:$D$27,2,FALSE) -> (0; 0,0707; 0,1414) | F20: =VLOOKUP(F6,'Thang đánh giá'!$C$2:$D$27,2,FALSE) -> (0; 0; 0) | G20: =VLOOKUP(G6,'Thang đánh giá'!$C$2:$D$27,2,FALSE) -> (0,0837; 0,1673; 0,251) | H20: =VLOOKUP(H6,'Thang đánh giá'!$C$2:$D$27,2,FALSE) -> (0; 0; 0,0707) | I20: =VLOOKUP(I6,'Thang đánh giá'!$C$2:$D$27,2,FALSE) -> (0; 0; 0,0548) | ... M20: =VLOOKUP(M6,'Thang đánh giá'!$C$2:$D$27,2,FALSE) -> (0; 0,0707; 0,1414)
A21: DRI7 | B21: =VLOOKUP(B7,'Thang đánh giá'!$C$2:$D$27,2,FALSE) -> (0; 0,0707; 0,1414) | C21: =VLOOKUP(C7,'Thang đánh giá'!$C$2:$D$27,2,FALSE) -> (0; 0; 0,0548) | D21: =VLOOKUP(D7,'Thang đánh giá'!$C$2:$D$27,2,FALSE) -> (0; 0,0548; 0,1095) | E21: =VLOOKUP(E7,'Thang đánh giá'!$C$2:$D$27,2,FALSE) -> (0; 0; 0,0707) | F21: =VLOOKUP(F7,'Thang đánh giá'!$C$2:$D$27,2,FALSE) -> (0; 0; 0,0707) | G21: =VLOOKUP(G7,'Thang đánh giá'!$C$2:$D$27,2,FALSE) -> (0; 0; 0) | H21: =VLOOKUP(H7,'Thang đánh giá'!$C$2:$D$27,2,FALSE) -> (0; 0,0707; 0,1414) | I21: =VLOOKUP(I7,'Thang đánh giá'!$C$2:$D$27,2,FALSE) -> (0; 0; 0,0707) | ... M21: =VLOOKUP(M7,'Thang đánh giá'!$C$2:$D$27,2,FALSE) -> (0; 0,0316; 0,0632)
A22: DRI9 | B22: =VLOOKUP(B8,'Thang đánh giá'!$C$2:$D$27,2,FALSE) -> (0; 0; 0,0707) | C22: =VLOOKUP(C8,'Thang đánh giá'!$C$2:$D$27,2,FALSE) -> (0; 0; 0,0548) | D22: =VLOOKUP(D8,'Thang đánh giá'!$C$2:$D$27,2,FALSE) -> (0; 0,0548; 0,1095) | E22: =VLOOKUP(E8,'Thang đánh giá'!$C$2:$D$27,2,FALSE) -> (0; 0; 0,0316) | F22: =VLOOKUP(F8,'Thang đánh giá'!$C$2:$D$27,2,FALSE) -> (0,0707; 0,1414; 0,2121) | G22: =VLOOKUP(G8,'Thang đánh giá'!$C$2:$D$27,2,FALSE) -> (0,0707; 0,1414; 0,2121) | H22: =VLOOKUP(H8,'Thang đánh giá'!$C$2:$D$27,2,FALSE) -> (0; 0; 0) | I22: =VLOOKUP(I8,'Thang đánh giá'!$C$2:$D$27,2,FALSE) -> (0; 0,0707; 0,1414) | ... M22: =VLOOKUP(M8,'Thang đánh giá'!$C$2:$D$27,2,FALSE) -> (0,0707; 0,1414; 0,2121)
A23: DRI10 | B23: =VLOOKUP(B9,'Thang đánh giá'!$C$2:$D$27,2,FALSE) -> (0; 0,0837; 0,1673) | C23: =VLOOKUP(C9,'Thang đánh giá'!$C$2:$D$27,2,FALSE) -> (0; 0; 0,0707) | D23: =VLOOKUP(D9,'Thang đánh giá'!$C$2:$D$27,2,FALSE) -> (0; 0,0707; 0,1414) | E23: =VLOOKUP(E9,'Thang đánh giá'!$C$2:$D$27,2,FALSE) -> (0; 0; 0,0707) | F23: =VLOOKUP(F9,'Thang đánh giá'!$C$2:$D$27,2,FALSE) -> (0; 0,0548; 0,1095) | G23: =VLOOKUP(G9,'Thang đánh giá'!$C$2:$D$27,2,FALSE) -> (0; 0,0548; 0,1095) | H23: =VLOOKUP(H9,'Thang đánh giá'!$C$2:$D$27,2,FALSE) -> (0; 0,0707; 0,1414) | I23: =VLOOKUP(I9,'Thang đánh giá'!$C$2:$D$27,2,FALSE) -> (0; 0; 0) | ... M23: =VLOOKUP(M9,'Thang đánh giá'!$C$2:$D$27,2,FALSE) -> (0,1897; 0,2846; 0,3795)
A24: DRI11 | B24: =VLOOKUP(B10,'Thang đánh giá'!$C$2:$D$27,2,FALSE) -> (0,1673; 0,251; 0,3347) | C24: =VLOOKUP(C10,'Thang đánh giá'!$C$2:$D$27,2,FALSE) -> (0; 0,0548; 0,1095) | D24: =VLOOKUP(D10,'Thang đánh giá'!$C$2:$D$27,2,FALSE) -> (0; 0,0548; 0,1095) | E24: =VLOOKUP(E10,'Thang đánh giá'!$C$2:$D$27,2,FALSE) -> (0; 0,0707; 0,1414) | F24: =VLOOKUP(F10,'Thang đánh giá'!$C$2:$D$27,2,FALSE) -> (0; 0; 0,0548) | G24: =VLOOKUP(G10,'Thang đánh giá'!$C$2:$D$27,2,FALSE) -> (0; 0; 0,0707) | H24: =VLOOKUP(H10,'Thang đánh giá'!$C$2:$D$27,2,FALSE) -> (0,1673; 0,251; 0,3347) | I24: =VLOOKUP(I10,'Thang đánh giá'!$C$2:$D$27,2,FALSE) -> (0; 0; 0,0707) | ... M24: =VLOOKUP(M10,'Thang đánh giá'!$C$2:$D$27,2,FALSE) -> (0,2846; 0,3795; 0,3795)
A25: DRI13 | B25: =VLOOKUP(B11,'Thang đánh giá'!$C$2:$D$27,2,FALSE) -> (0; 0,0707; 0,1414) | C25: =VLOOKUP(C11,'Thang đánh giá'!$C$2:$D$27,2,FALSE) -> (0; 0,0837; 0,1673) | D25: =VLOOKUP(D11,'Thang đánh giá'!$C$2:$D$27,2,FALSE) -> (0; 0,0548; 0,1095) | E25: =VLOOKUP(E11,'Thang đánh giá'!$C$2:$D$27,2,FALSE) -> (0; 0,0707; 0,1414) | F25: =VLOOKUP(F11,'Thang đánh giá'!$C$2:$D$27,2,FALSE) -> (0,0707; 0,1414; 0,2121) | G25: =VLOOKUP(G11,'Thang đánh giá'!$C$2:$D$27,2,FALSE) -> (0; 0,0548; 0,1095) | H25: =VLOOKUP(H11,'Thang đánh giá'!$C$2:$D$27,2,FALSE) -> (0; 0; 0,0548) | I25: =VLOOKUP(I11,'Thang đánh giá'!$C$2:$D$27,2,FALSE) -> (0; 0,0548; 0,1095) | ... M25: =VLOOKUP(M11,'Thang đánh giá'!$C$2:$D$27,2,FALSE) -> (0; 0,0548; 0,1095)
A26: DRI14 | B26: =VLOOKUP(B12,'Thang đánh giá'!$C$2:$D$27,2,FALSE) -> (0; 0; 0,0707) | C26: =VLOOKUP(C12,'Thang đánh giá'!$C$2:$D$27,2,FALSE) -> (0; 0,0707; 0,1414) | D26: =VLOOKUP(D12,'Thang đánh giá'!$C$2:$D$27,2,FALSE) -> (0; 0; 0,0316) | E26: =VLOOKUP(E12,'Thang đánh giá'!$C$2:$D$27,2,FALSE) -> (0; 0; 0,0707) | F26: =VLOOKUP(F12,'Thang đánh giá'!$C$2:$D$27,2,FALSE) -> (0; 0; 0,0707) | G26: =VLOOKUP(G12,'Thang đánh giá'!$C$2:$D$27,2,FALSE) -> (0; 0; 0,0837) | H26: =VLOOKUP(H12,'Thang đánh giá'!$C$2:$D$27,2,FALSE) -> (0; 0,0548; 0,1095) | I26: =VLOOKUP(I12,'Thang đánh giá'!$C$2:$D$27,2,FALSE) -> (0; 0; 0,0707) | ... M26: =VLOOKUP(M12,'Thang đánh giá'!$C$2:$D$27,2,FALSE) -> (0,1897; 0,2846; 0,3795)
A27: DRI15 | B27: =VLOOKUP(B13,'Thang đánh giá'!$C$2:$D$27,2,FALSE) -> (0; 0; 0,0548) | C27: =VLOOKUP(C13,'Thang đánh giá'!$C$2:$D$27,2,FALSE) -> (0; 0,0837; 0,1673) | D27: =VLOOKUP(D13,'Thang đánh giá'!$C$2:$D$27,2,FALSE) -> (0; 0; 0,0707) | E27: =VLOOKUP(E13,'Thang đánh giá'!$C$2:$D$27,2,FALSE) -> (0,0707; 0,1414; 0,2121) | F27: =VLOOKUP(F13,'Thang đánh giá'!$C$2:$D$27,2,FALSE) -> (0; 0; 0,0548) | G27: =VLOOKUP(G13,'Thang đánh giá'!$C$2:$D$27,2,FALSE) -> (0; 0; 0,0707) | H27: =VLOOKUP(H13,'Thang đánh giá'!$C$2:$D$27,2,FALSE) -> (0; 0; 0,0316) | I27: =VLOOKUP(I13,'Thang đánh giá'!$C$2:$D$27,2,FALSE) -> (0; 0,0548; 0,1095) | ... M27: =VLOOKUP(M13,'Thang đánh giá'!$C$2:$D$27,2,FALSE) -> (0; 0; 0)
A29: L | B29: DRI1 | C29: DRI3 | D29: DRI4 | E29: DRI5 | F29: DRI6 | G29: DRI7 | H29: DRI9 | I29: DRI10 | J29: DRI11 | K29: DRI13 | L29: DRI14 | M29: DRI15
A30: DRI1 | B30: =_xlfn.NUMBERVALUE(MID(B16,2,FIND(";",B16,1)-2)) -> 0 | C30: =_xlfn.NUMBERVALUE(MID(C16,2,FIND(";",C16,1)-2)) -> 0.1673 | D30: =_xlfn.NUMBERVALUE(MID(D16,2,FIND(";",D16,1)-2)) -> 0.1897 | E30: =_xlfn.NUMBERVALUE(MID(E16,2,FIND(";",E16,1)-2)) -> 0.0837 | F30: =_xlfn.NUMBERVALUE(MID(F16,2,FIND(";",F16,1)-2)) -> 0 | G30: =_xlfn.NUMBERVALUE(MID(G16,2,FIND(";",G16,1)-2)) -> 0 | H30: =_xlfn.NUMBERVALUE(MID(H16,2,FIND(";",H16,1)-2)) -> 0 | I30: =_xlfn.NUMBERVALUE(MID(I16,2,FIND(";",I16,1)-2)) -> 0 | ... M30: =_xlfn.NUMBERVALUE(MID(M16,2,FIND(";",M16,1)-2)) -> 0
A31: DRI3 | B31: =_xlfn.NUMBERVALUE(MID(B17,2,FIND(";",B17,1)-2)) -> 0 | C31: =_xlfn.NUMBERVALUE(MID(C17,2,FIND(";",C17,1)-2)) -> 0 | D31: =_xlfn.NUMBERVALUE(MID(D17,2,FIND(";",D17,1)-2)) -> 0.2846 | E31: =_xlfn.NUMBERVALUE(MID(E17,2,FIND(";",E17,1)-2)) -> 0.2846 | F31: =_xlfn.NUMBERVALUE(MID(F17,2,FIND(";",F17,1)-2)) -> 0 | G31: =_xlfn.NUMBERVALUE(MID(G17,2,FIND(";",G17,1)-2)) -> 0 | H31: =_xlfn.NUMBERVALUE(MID(H17,2,FIND(";",H17,1)-2)) -> 0.1897 | I31: =_xlfn.NUMBERVALUE(MID(I17,2,FIND(";",I17,1)-2)) -> 0 | ... M31: =_xlfn.NUMBERVALUE(MID(M17,2,FIND(";",M17,1)-2)) -> 0.1897
A32: DRI4 | B32: =_xlfn.NUMBERVALUE(MID(B18,2,FIND(";",B18,1)-2)) -> 0 | C32: =_xlfn.NUMBERVALUE(MID(C18,2,FIND(";",C18,1)-2)) -> 0 | D32: =_xlfn.NUMBERVALUE(MID(D18,2,FIND(";",D18,1)-2)) -> 0 | E32: =_xlfn.NUMBERVALUE(MID(E18,2,FIND(";",E18,1)-2)) -> 0.1414 | F32: =_xlfn.NUMBERVALUE(MID(F18,2,FIND(";",F18,1)-2)) -> 0 | G32: =_xlfn.NUMBERVALUE(MID(G18,2,FIND(";",G18,1)-2)) -> 0.0837 | H32: =_xlfn.NUMBERVALUE(MID(H18,2,FIND(";",H18,1)-2)) -> 0 | I32: =_xlfn.NUMBERVALUE(MID(I18,2,FIND(";",I18,1)-2)) -> 0 | ... M32: =_xlfn.NUMBERVALUE(MID(M18,2,FIND(";",M18,1)-2)) -> 0.2846
A33: DRI5 | B33: =_xlfn.NUMBERVALUE(MID(B19,2,FIND(";",B19,1)-2)) -> 0.0707 | C33: =_xlfn.NUMBERVALUE(MID(C19,2,FIND(";",C19,1)-2)) -> 0 | D33: =_xlfn.NUMBERVALUE(MID(D19,2,FIND(";",D19,1)-2)) -> 0 | E33: =_xlfn.NUMBERVALUE(MID(E19,2,FIND(";",E19,1)-2)) -> 0 | F33: =_xlfn.NUMBERVALUE(MID(F19,2,FIND(";",F19,1)-2)) -> 0.1673 | G33: =_xlfn.NUMBERVALUE(MID(G19,2,FIND(";",G19,1)-2)) -> 0 | H33: =_xlfn.NUMBERVALUE(MID(H19,2,FIND(";",H19,1)-2)) -> 0.1897 | I33: =_xlfn.NUMBERVALUE(MID(I19,2,FIND(";",I19,1)-2)) -> 0 | ... M33: =_xlfn.NUMBERVALUE(MID(M19,2,FIND(";",M19,1)-2)) -> 0.2846
A34: DRI6 | B34: =_xlfn.NUMBERVALUE(MID(B20,2,FIND(";",B20,1)-2)) -> 0 | C34: =_xlfn.NUMBERVALUE(MID(C20,2,FIND(";",C20,1)-2)) -> 0 | D34: =_xlfn.NUMBERVALUE(MID(D20,2,FIND(";",D20,1)-2)) -> 0 | E34: =_xlfn.NUMBERVALUE(MID(E20,2,FIND(";",E20,1)-2)) -> 0 | F34: =_xlfn.NUMBERVALUE(MID(F20,2,FIND(";",F20,1)-2)) -> 0 | G34: =_xlfn.NUMBERVALUE(MID(G20,2,FIND(";",G20,1)-2)) -> 0.0837 | H34: =_xlfn.NUMBERVALUE(MID(H20,2,FIND(";",H20,1)-2)) -> 0 | I34: =_xlfn.NUMBERVALUE(MID(I20,2,FIND(";",I20,1)-2)) -> 0 | ... M34: =_xlfn.NUMBERVALUE(MID(M20,2,FIND(";",M20,1)-2)) -> 0
A35: DRI7 | B35: =_xlfn.NUMBERVALUE(MID(B21,2,FIND(";",B21,1)-2)) -> 0 | C35: =_xlfn.NUMBERVALUE(MID(C21,2,FIND(";",C21,1)-2)) -> 0 | D35: =_xlfn.NUMBERVALUE(MID(D21,2,FIND(";",D21,1)-2)) -> 0 | E35: =_xlfn.NUMBERVALUE(MID(E21,2,FIND(";",E21,1)-2)) -> 0 | F35: =_xlfn.NUMBERVALUE(MID(F21,2,FIND(";",F21,1)-2)) -> 0 | G35: =_xlfn.NUMBERVALUE(MID(G21,2,FIND(";",G21,1)-2)) -> 0 | H35: =_xlfn.NUMBERVALUE(MID(H21,2,FIND(";",H21,1)-2)) -> 0 | I35: =_xlfn.NUMBERVALUE(MID(I21,2,FIND(";",I21,1)-2)) -> 0 | ... M35: =_xlfn.NUMBERVALUE(MID(M21,2,FIND(";",M21,1)-2)) -> 0
A36: DRI9 | B36: =_xlfn.NUMBERVALUE(MID(B22,2,FIND(";",B22,1)-2)) -> 0 | C36: =_xlfn.NUMBERVALUE(MID(C22,2,FIND(";",C22,1)-2)) -> 0 | D36: =_xlfn.NUMBERVALUE(MID(D22,2,FIND(";",D22,1)-2)) -> 0 | E36: =_xlfn.NUMBERVALUE(MID(E22,2,FIND(";",E22,1)-2)) -> 0 | F36: =_xlfn.NUMBERVALUE(MID(F22,2,FIND(";",F22,1)-2)) -> 0.0707 | G36: =_xlfn.NUMBERVALUE(MID(G22,2,FIND(";",G22,1)-2)) -> 0.0707 | H36: =_xlfn.NUMBERVALUE(MID(H22,2,FIND(";",H22,1)-2)) -> 0 | I36: =_xlfn.NUMBERVALUE(MID(I22,2,FIND(";",I22,1)-2)) -> 0 | ... M36: =_xlfn.NUMBERVALUE(MID(M22,2,FIND(";",M22,1)-2)) -> 0.0707
A37: DRI10 | B37: =_xlfn.NUMBERVALUE(MID(B23,2,FIND(";",B23,1)-2)) -> 0 | C37: =_xlfn.NUMBERVALUE(MID(C23,2,FIND(";",C23,1)-2)) -> 0 | D37: =_xlfn.NUMBERVALUE(MID(D23,2,FIND(";",D23,1)-2)) -> 0 | E37: =_xlfn.NUMBERVALUE(MID(E23,2,FIND(";",E23,1)-2)) -> 0 | F37: =_xlfn.NUMBERVALUE(MID(F23,2,FIND(";",F23,1)-2)) -> 0 | G37: =_xlfn.NUMBERVALUE(MID(G23,2,FIND(";",G23,1)-2)) -> 0 | H37: =_xlfn.NUMBERVALUE(MID(H23,2,FIND(";",H23,1)-2)) -> 0 | I37: =_xlfn.NUMBERVALUE(MID(I23,2,FIND(";",I23,1)-2)) -> 0 | ... M37: =_xlfn.NUMBERVALUE(MID(M23,2,FIND(";",M23,1)-2)) -> 0.1897
A38: DRI11 | B38: =_xlfn.NUMBERVALUE(MID(B24,2,FIND(";",B24,1)-2)) -> 0.1673 | C38: =_xlfn.NUMBERVALUE(MID(C24,2,FIND(";",C24,1)-2)) -> 0 | D38: =_xlfn.NUMBERVALUE(MID(D24,2,FIND(";",D24,1)-2)) -> 0 | E38: =_xlfn.NUMBERVALUE(MID(E24,2,FIND(";",E24,1)-2)) -> 0 | F38: =_xlfn.NUMBERVALUE(MID(F24,2,FIND(";",F24,1)-2)) -> 0 | G38: =_xlfn.NUMBERVALUE(MID(G24,2,FIND(";",G24,1)-2)) -> 0 | H38: =_xlfn.NUMBERVALUE(MID(H24,2,FIND(";",H24,1)-2)) -> 0.1673 | I38: =_xlfn.NUMBERVALUE(MID(I24,2,FIND(";",I24,1)-2)) -> 0 | ... M38: =_xlfn.NUMBERVALUE(MID(M24,2,FIND(";",M24,1)-2)) -> 0.2846
A39: DRI13 | B39: =_xlfn.NUMBERVALUE(MID(B25,2,FIND(";",B25,1)-2)) -> 0 | C39: =_xlfn.NUMBERVALUE(MID(C25,2,FIND(";",C25,1)-2)) -> 0 | D39: =_xlfn.NUMBERVALUE(MID(D25,2,FIND(";",D25,1)-2)) -> 0 | E39: =_xlfn.NUMBERVALUE(MID(E25,2,FIND(";",E25,1)-2)) -> 0 | F39: =_xlfn.NUMBERVALUE(MID(F25,2,FIND(";",F25,1)-2)) -> 0.0707 | G39: =_xlfn.NUMBERVALUE(MID(G25,2,FIND(";",G25,1)-2)) -> 0 | H39: =_xlfn.NUMBERVALUE(MID(H25,2,FIND(";",H25,1)-2)) -> 0 | I39: =_xlfn.NUMBERVALUE(MID(I25,2,FIND(";",I25,1)-2)) -> 0 | ... M39: =_xlfn.NUMBERVALUE(MID(M25,2,FIND(";",M25,1)-2)) -> 0
A40: DRI14 | B40: =_xlfn.NUMBERVALUE(MID(B26,2,FIND(";",B26,1)-2)) -> 0 | C40: =_xlfn.NUMBERVALUE(MID(C26,2,FIND(";",C26,1)-2)) -> 0 | D40: =_xlfn.NUMBERVALUE(MID(D26,2,FIND(";",D26,1)-2)) -> 0 | E40: =_xlfn.NUMBERVALUE(MID(E26,2,FIND(";",E26,1)-2)) -> 0 | F40: =_xlfn.NUMBERVALUE(MID(F26,2,FIND(";",F26,1)-2)) -> 0 | G40: =_xlfn.NUMBERVALUE(MID(G26,2,FIND(";",G26,1)-2)) -> 0 | H40: =_xlfn.NUMBERVALUE(MID(H26,2,FIND(";",H26,1)-2)) -> 0 | I40: =_xlfn.NUMBERVALUE(MID(I26,2,FIND(";",I26,1)-2)) -> 0 | ... M40: =_xlfn.NUMBERVALUE(MID(M26,2,FIND(";",M26,1)-2)) -> 0.1897
A41: DRI15 | B41: =_xlfn.NUMBERVALUE(MID(B27,2,FIND(";",B27,1)-2)) -> 0 | C41: =_xlfn.NUMBERVALUE(MID(C27,2,FIND(";",C27,1)-2)) -> 0 | D41: =_xlfn.NUMBERVALUE(MID(D27,2,FIND(";",D27,1)-2)) -> 0 | E41: =_xlfn.NUMBERVALUE(MID(E27,2,FIND(";",E27,1)-2)) -> 0.0707 | F41: =_xlfn.NUMBERVALUE(MID(F27,2,FIND(";",F27,1)-2)) -> 0 | G41: =_xlfn.NUMBERVALUE(MID(G27,2,FIND(";",G27,1)-2)) -> 0 | H41: =_xlfn.NUMBERVALUE(MID(H27,2,FIND(";",H27,1)-2)) -> 0 | I41: =_xlfn.NUMBERVALUE(MID(I27,2,FIND(";",I27,1)-2)) -> 0 | ... M41: =_xlfn.NUMBERVALUE(MID(M27,2,FIND(";",M27,1)-2)) -> 0
A43: M | B43: DRI1 | C43: DRI3 | D43: DRI4 | E43: DRI5 | F43: DRI6 | G43: DRI7 | H43: DRI9 | I43: DRI10 | J43: DRI11 | K43: DRI13 | L43: DRI14 | M43: DRI15
...

Sheet Ans 2
B1: DRI1 | C1: DRI3 | D1: DRI4 | E1: DRI5 | F1: DRI6 | G1: DRI7 | H1: DRI9 | I1: DRI10 | J1: DRI11 | K1: DRI13 | L1: DRI14 | M1: DRI15
A2: DRI1 | B2: 0 | C2: VI;VH | D2: VI;VH | E2: NI;M | F2: VI;H | G2: NI;M | H2: FI;M | I2: WI;M | J2: VI;VH | K2: NI;M | L2: WI;L | M2: NI;M
A3: DRI3 | B3: FI;M | C3: 0 | D3: AI;VH | E3: AI;H | F3: WI;M | G3: AI;VH | H3: AI;VH | I3: NI;M | J3: AI;H | K3: AI;VH | L3: VI;VH | M3: AI;VH
A4: DRI4 | B4: VI;H | C4: NI;M | D4: 0 | E4: VI;M | F4: WI;L | G4: WI;L | H4: VI;H | I4: WI;M | J4: AI;H | K4: AI;VH | L4: VI;H | M4: AI;VH
A5: DRI5 | B5: NI;M | C5: FI;H | D5: NI;M | E5: 0 | F5: VI;H | G5: NI;L | H5: VI;VH | I5: NI;M | J5: AI;H | K5: NI;L | L5: VI;H | M5: WI;L
A6: DRI6 | B6: WI;VL | C6: WI;M | D6: NI;M | E6: NI;VL | F6: 0 | G6: VI;VH | H6: NI;H | I6: WI;M | J6: VI;VH | K6: VI;VH | L6: WI;VL | M6: NI;M
A7: DRI7 | B7: WI;M | C7: FI;M | D7: WI;L | E7: NI;L | F7: NI;M | G7: 0 | H7: NI;M | I7: FI;H | J7: VI;H | K7: WI;M | L7: NI;L | M7: WI;L
A8: DRI9 | B8: NI;L | C8: WI;M | D8: WI;L | E8: WI;H | F8: NI;M | G8: NI;M | H8: 0 | I8: FI;M | J8: WI;L | K8: NI;M | L8: NI;M | M8: NI;M
A9: DRI10 | B9: NI;M | C9: NI;M | D9: NI;M | E9: NI;H | F9: WI;M | G9: FI;M | H9: NI;H | I9: 0 | J9: NI;M | K9: AI;VH | L9: VI;H | M9: VI;VH
A10: DRI11 | B10: FI;H | C10: WI;L | D10: WI;M | E10: NI;M | F10: NI;L | G10: WI;M | H10: VI;VH | I10: NI;M | J10: 0 | K10: AI;H | L10: AI;H | M10: VI;VH
A11: DRI13 | B11: WI;L | C11: NI;M | D11: NI;L | E11: NI;L | F11: NI;L | G11: NI;L | H11: NI;H | I11: WI;M | J11: NI;L | K11: 0 | L11: NI;L | M11: NI;M
A12: DRI14 | B12: NI;L | C12: WI;L | D12: NI;M | E12: NI;M | F12: WI;M | G12: NI;M | H12: NI;VL | I12: FI;M | J12: NI;M | K12: WI;VL | L12: 0 | M12: VI;VH
A13: DRI15 | B13: WI;M | C13: NI;M | D13: NI;L | E13: NI;M | F13: WI;M | G13: FI;H | H13: NI;L | I13: NI;H | J13: FI;M | K13: NI;L | L13: NI;M | M13: 0
B15: DRI1 | C15: DRI3 | D15: DRI4 | E15: DRI5 | F15: DRI6 | G15: DRI7 | H15: DRI9 | I15: DRI10 | J15: DRI11 | K15: DRI13 | L15: DRI14 | M15: DRI15
A16: DRI1 | B16: =VLOOKUP(B2,'Thang đánh giá'!$C$2:$D$27,2,FALSE) -> (0; 0; 0) | C16: =VLOOKUP(C2,'Thang đánh giá'!$C$2:$D$27,2,FALSE) -> (0,1897; 0,2846; 0,3795) | D16: =VLOOKUP(D2,'Thang đánh giá'!$C$2:$D$27,2,FALSE) -> (0,1897; 0,2846; 0,3795) | E16: =VLOOKUP(E2,'Thang đánh giá'!$C$2:$D$27,2,FALSE) -> (0; 0; 0,0707) | F16: =VLOOKUP(F2,'Thang đánh giá'!$C$2:$D$27,2,FALSE) -> (0,1673; 0,251; 0,3347) | G16: =VLOOKUP(G2,'Thang đánh giá'!$C$2:$D$27,2,FALSE) -> (0; 0; 0,0707) | H16: =VLOOKUP(H2,'Thang đánh giá'!$C$2:$D$27,2,FALSE) -> (0,0707; 0,1414; 0,2121) | I16: =VLOOKUP(I2,'Thang đánh giá'!$C$2:$D$27,2,FALSE) -> (0; 0,0707; 0,1414) | ... M16: =VLOOKUP(M2,'Thang đánh giá'!$C$2:$D$27,2,FALSE) -> (0; 0; 0,0707)
A17: DRI3 | B17: =VLOOKUP(B3,'Thang đánh giá'!$C$2:$D$27,2,FALSE) -> (0,0707; 0,1414; 0,2121) | C17: =VLOOKUP(C3,'Thang đánh giá'!$C$2:$D$27,2,FALSE) -> (0; 0; 0) | D17: =VLOOKUP(D3,'Thang đánh giá'!$C$2:$D$27,2,FALSE) -> (0,2846; 0,3795; 0,3795) | E17: =VLOOKUP(E3,'Thang đánh giá'!$C$2:$D$27,2,FALSE) -> (0,251; 0,3347; 0,3347) | F17: =VLOOKUP(F3,'Thang đánh giá'!$C$2:$D$27,2,FALSE) -> (0; 0,0707; 0,1414) | G17: =VLOOKUP(G3,'Thang đánh giá'!$C$2:$D$27,2,FALSE) -> (0,2846; 0,3795; 0,3795) | H17: =VLOOKUP(H3,'Thang đánh giá'!$C$2:$D$27,2,FALSE) -> (0,2846; 0,3795; 0,3795) | I17: =VLOOKUP(I3,'Thang đánh giá'!$C$2:$D$27,2,FALSE) -> (0; 0; 0,0707) | ... M17: =VLOOKUP(M3,'Thang đánh giá'!$C$2:$D$27,2,FALSE) -> (0,2846; 0,3795; 0,3795)
A18: DRI4 | B18: =VLOOKUP(B4,'Thang đánh giá'!$C$2:$D$27,2,FALSE) -> (0,1673; 0,251; 0,3347) | C18: =VLOOKUP(C4,'Thang đánh giá'!$C$2:$D$27,2,FALSE) -> (0; 0; 0,0707) | D18: =VLOOKUP(D4,'Thang đánh giá'!$C$2:$D$27,2,FALSE) -> (0; 0; 0) | E18: =VLOOKUP(E4,'Thang đánh giá'!$C$2:$D$27,2,FALSE) -> (0,1414; 0,2121; 0,2828) | F18: =VLOOKUP(F4,'Thang đánh giá'!$C$2:$D$27,2,FALSE) -> (0; 0,0548; 0,1095) | G18: =VLOOKUP(G4,'Thang đánh giá'!$C$2:$D$27,2,FALSE) -> (0; 0,0548; 0,1095) | H18: =VLOOKUP(H4,'Thang đánh giá'!$C$2:$D$27,2,FALSE) -> (0,1673; 0,251; 0,3347) | I18: =VLOOKUP(I4,'Thang đánh giá'!$C$2:$D$27,2,FALSE) -> (0; 0,0707; 0,1414) | ... M18: =VLOOKUP(M4,'Thang đánh giá'!$C$2:$D$27,2,FALSE) -> (0,2846; 0,3795; 0,3795)
A19: DRI5 | B19: =VLOOKUP(B5,'Thang đánh giá'!$C$2:$D$27,2,FALSE) -> (0; 0; 0,0707) | C19: =VLOOKUP(C5,'Thang đánh giá'!$C$2:$D$27,2,FALSE) -> (0,0837; 0,1673; 0,251) | D19: =VLOOKUP(D5,'Thang đánh giá'!$C$2:$D$27,2,FALSE) -> (0; 0; 0,0707) | E19: =VLOOKUP(E5,'Thang đánh giá'!$C$2:$D$27,2,FALSE) -> (0; 0; 0) | F19: =VLOOKUP(F5,'Thang đánh giá'!$C$2:$D$27,2,FALSE) -> (0,1673; 0,251; 0,3347) | G19: =VLOOKUP(G5,'Thang đánh giá'!$C$2:$D$27,2,FALSE) -> (0; 0; 0,0548) | H19: =VLOOKUP(H5,'Thang đánh giá'!$C$2:$D$27,2,FALSE) -> (0,1897; 0,2846; 0,3795) | I19: =VLOOKUP(I5,'Thang đánh giá'!$C$2:$D$27,2,FALSE) -> (0; 0; 0,0707) | ... M19: =VLOOKUP(M5,'Thang đánh giá'!$C$2:$D$27,2,FALSE) -> (0; 0,0548; 0,1095)
A20: DRI6 | B20: =VLOOKUP(B6,'Thang đánh giá'!$C$2:$D$27,2,FALSE) -> (0; 0,0316; 0,0632) | C20: =VLOOKUP(C6,'Thang đánh giá'!$C$2:$D$27,2,FALSE) -> (0; 0,0707; 0,1414) | D20: =VLOOKUP(D6,'Thang đánh giá'!$C$2:$D$27,2,FALSE) -> (0; 0; 0,0707) | E20: =VLOOKUP(E6,'Thang đánh giá'!$C$2:$D$27,2,FALSE) -> (0; 0; 0,0316) | F20: =VLOOKUP(F6,'Thang đánh giá'!$C$2:$D$27,2,FALSE) -> (0; 0; 0) | G20: =VLOOKUP(G6,'Thang đánh giá'!$C$2:$D$27,2,FALSE) -> (0,1897; 0,2846; 0,3795) | H20: =VLOOKUP(H6,'Thang đánh giá'!$C$2:$D$27,2,FALSE) -> (0; 0; 0,0837) | I20: =VLOOKUP(I6,'Thang đánh giá'!$C$2:$D$27,2,FALSE) -> (0; 0,0707; 0,1414) | ... M20: =VLOOKUP(M6,'Thang đánh giá'!$C$2:$D$27,2,FALSE) -> (0; 0; 0,0707)
A21: DRI7 | B21: =VLOOKUP(B7,'Thang đánh giá'!$C$2:$D$27,2,FALSE) -> (0; 0,0707; 0,1414) | C21: =VLOOKUP(C7,'Thang đánh giá'!$C$2:$D$27,2,FALSE) -> (0,0707; 0,1414; 0,2121) | D21: =VLOOKUP(D7,'Thang đánh giá'!$C$2:$D$27,2,FALSE) -> (0; 0,0548; 0,1095) | E21: =VLOOKUP(E7,'Thang đánh giá'!$C$2:$D$27,2,FALSE) -> (0; 0; 0,0548) | F21: =VLOOKUP(F7,'Thang đánh giá'!$C$2:$D$27,2,FALSE) -> (0; 0; 0,0707) | G21: =VLOOKUP(G7,'Thang đánh giá'!$C$2:$D$27,2,FALSE) -> (0; 0; 0) | H21: =VLOOKUP(H7,'Thang đánh giá'!$C$2:$D$27,2,FALSE) -> (0; 0; 0,0707) | I21: =VLOOKUP(I7,'Thang đánh giá'!$C$2:$D$27,2,FALSE) -> (0,0837; 0,1673; 0,251) | ... M21: =VLOOKUP(M7,'Thang đánh giá'!$C$2:$D$27,2,FALSE) -> (0; 0,0548; 0,1095)
A22: DRI9 | B22: =VLOOKUP(B8,'Thang đánh giá'!$C$2:$D$27,2,FALSE) -> (0; 0; 0,0548) | C22: =VLOOKUP(C8,'Thang đánh giá'!$C$2:$D$27,2,FALSE) -> (0; 0,0707; 0,1414) | D22: =VLOOKUP(D8,'Thang đánh giá'!$C$2:$D$27,2,FALSE) -> (0; 0,0548; 0,1095) | E22: =VLOOKUP(E8,'Thang đánh giá'!$C$2:$D$27,2,FALSE) -> (0; 0,0837; 0,1673) | F22: =VLOOKUP(F8,'Thang đánh giá'!$C$2:$D$27,2,FALSE) -> (0; 0; 0,0707) | G22: =VLOOKUP(G8,'Thang đánh giá'!$C$2:$D$27,2,FALSE) -> (0; 0; 0,0707) | H22: =VLOOKUP(H8,'Thang đánh giá'!$C$2:$D$27,2,FALSE) -> (0; 0; 0) | I22: =VLOOKUP(I8,'Thang đánh giá'!$C$2:$D$27,2,FALSE) -> (0,0707; 0,1414; 0,2121) | ... M22: =VLOOKUP(M8,'Thang đánh giá'!$C$2:$D$27,2,FALSE) -> (0; 0; 0,0707)
A23: DRI10 | B23: =VLOOKUP(B9,'Thang đánh giá'!$C$2:$D$27,2,FALSE) -> (0; 0; 0,0707) | C23: =VLOOKUP(C9,'Thang đánh giá'!$C$2:$D$27,2,FALSE) -> (0; 0; 0,0707) | D23: =VLOOKUP(D9,'Thang đánh giá'!$C$2:$D$27,2,FALSE) -> (0; 0; 0,0707) | E23: =VLOOKUP(E9,'Thang đánh giá'!$C$2:$D$27,2,FALSE) -> (0; 0; 0,0837) | F23: =VLOOKUP(F9,'Thang đánh giá'!$C$2:$D$27,2,FALSE) -> (0; 0,0707; 0,1414) | G23: =VLOOKUP(G9,'Thang đánh giá'!$C$2:$D$27,2,FALSE) -> (0,0707; 0,1414; 0,2121) | H23: =VLOOKUP(H9,'Thang đánh giá'!$C$2:$D$27,2,FALSE) -> (0; 0; 0,0837) | I23: =VLOOKUP(I9,'Thang đánh giá'!$C$2:$D$27,2,FALSE) -> (0; 0; 0) | ... M23: =VLOOKUP(M9,'Thang đánh giá'!$C$2:$D$27,2,FALSE) -> (0,1897; 0,2846; 0,3795)
A24: DRI11 | B24: =VLOOKUP(B10,'Thang đánh giá'!$C$2:$D$27,2,FALSE) -> (0,0837; 0,1673; 0,251) | C24: =VLOOKUP(C10,'Thang đánh giá'!$C$2:$D$27,2,FALSE) -> (0; 0,0548; 0,1095) | D24: =VLOOKUP(D10,'Thang đánh giá'!$C$2:$D$27,2,FALSE) -> (0; 0,0707; 0,1414) | E24: =VLOOKUP(E10,'Thang đánh giá'!$C$2:$D$27,2,FALSE) -> (0; 0; 0,0707) | F24: =VLOOKUP(F10,'Thang đánh giá'!$C$2:$D$27,2,FALSE) -> (0; 0; 0,0548) | G24: =VLOOKUP(G10,'Thang đánh giá'!$C$2:$D$27,2,FALSE) -> (0; 0,0707; 0,1414) | H24: =VLOOKUP(H10,'Thang đánh giá'!$C$2:$D$27,2,FALSE) -> (0,1897; 0,2846; 0,3795) | I24: =VLOOKUP(I10,'Thang đánh giá'!$C$2:$D$27,2,FALSE) -> (0; 0; 0,0707) | ... M24: =VLOOKUP(M10,'Thang đánh giá'!$C$2:$D$27,2,FALSE) -> (0,1897; 0,2846; 0,3795)
A25: DRI13 | B25: =VLOOKUP(B11,'Thang đánh giá'!$C$2:$D$27,2,FALSE) -> (0; 0,0548; 0,1095) | C25: =VLOOKUP(C11,'Thang đánh giá'!$C$2:$D$27,2,FALSE) -> (0; 0; 0,0707) | D25: =VLOOKUP(D11,'Thang đánh giá'!$C$2:$D$27,2,FALSE) -> (0; 0; 0,0548) | E25: =VLOOKUP(E11,'Thang đánh giá'!$C$2:$D$27,2,FALSE) -> (0; 0; 0,0548) | F25: =VLOOKUP(F11,'Thang đánh giá'!$C$2:$D$27,2,FALSE) -> (0; 0; 0,0548) | G25: =VLOOKUP(G11,'Thang đánh giá'!$C$2:$D$27,2,FALSE) -> (0; 0; 0,0548) | H25: =VLOOKUP(H11,'Thang đánh giá'!$C$2:$D$27,2,FALSE) -> (0; 0; 0,0837) | I25: =VLOOKUP(I11,'Thang đánh giá'!$C$2:$D$27,2,FALSE) -> (0; 0,0707; 0,1414) | ... M25: =VLOOKUP(M11,'Thang đánh giá'!$C$2:$D$27,2,FALSE) -> (0; 0; 0,0707)
A26: DRI14 | B26: =VLOOKUP(B12,'Thang đánh giá'!$C$2:$D$27,2,FALSE) -> (0; 0; 0,0548) | C26: =VLOOKUP(C12,'Thang đánh giá'!$C$2:$D$27,2,FALSE) -> (0; 0,0548; 0,1095) | D26: =VLOOKUP(D12,'Thang đánh giá'!$C$2:$D$27,2,FALSE) -> (0; 0; 0,0707) | E26: =VLOOKUP(E12,'Thang đánh giá'!$C$2:$D$27,2,FALSE) -> (0; 0; 0,0707) | F26: =VLOOKUP(F12,'Thang đánh giá'!$C$2:$D$27,2,FALSE) -> (0; 0,0707; 0,1414) | G26: =VLOOKUP(G12,'Thang đánh giá'!$C$2:$D$27,2,FALSE) -> (0; 0; 0,0707) | H26: =VLOOKUP(H12,'Thang đánh giá'!$C$2:$D$27,2,FALSE) -> (0; 0; 0,0316) | I26: =VLOOKUP(I12,'Thang đánh giá'!$C$2:$D$27,2,FALSE) -> (0,0707; 0,1414; 0,2121) | ... M26: =VLOOKUP(M12,'Thang đánh giá'!$C$2:$D$27,2,FALSE) -> (0,1897; 0,2846; 0,3795)
A27: DRI15 | B27: =VLOOKUP(B13,'Thang đánh giá'!$C$2:$D$27,2,FALSE) -> (0; 0,0707; 0,1414) | C27: =VLOOKUP(C13,'Thang đánh giá'!$C$2:$D$27,2,FALSE) -> (0; 0; 0,0707) | D27: =VLOOKUP(D13,'Thang đánh giá'!$C$2:$D$27,2,FALSE) -> (0; 0; 0,0548) | E27: =VLOOKUP(E13,'Thang đánh giá'!$C$2:$D$27,2,FALSE) -> (0; 0; 0,0707) | F27: =VLOOKUP(F13,'Thang đánh giá'!$C$2:$D$27,2,FALSE) -> (0; 0,0707; 0,1414) | G27: =VLOOKUP(G13,'Thang đánh giá'!$C$2:$D$27,2,FALSE) -> (0,0837; 0,1673; 0,251) | H27: =VLOOKUP(H13,'Thang đánh giá'!$C$2:$D$27,2,FALSE) -> (0; 0; 0,0548) | I27: =VLOOKUP(I13,'Thang đánh giá'!$C$2:$D$27,2,FALSE) -> (0; 0; 0,0837) | ... M27: =VLOOKUP(M13,'Thang đánh giá'!$C$2:$D$27,2,FALSE) -> (0; 0; 0)
A29: L | B29: DRI1 | C29: DRI3 | D29: DRI4 | E29: DRI5 | F29: DRI6 | G29: DRI7 | H29: DRI9 | I29: DRI10 | J29: DRI11 | K29: DRI13 | L29: DRI14 | M29: DRI15
A30: DRI1 | B30: =_xlfn.NUMBERVALUE(MID(B16,2,FIND(";",B16,1)-2)) -> 0 | C30: =_xlfn.NUMBERVALUE(MID(C16,2,FIND(";",C16,1)-2)) -> 0.1897 | D30: =_xlfn.NUMBERVALUE(MID(D16,2,FIND(";",D16,1)-2)) -> 0.1897 | E30: =_xlfn.NUMBERVALUE(MID(E16,2,FIND(";",E16,1)-2)) -> 0 | F30: =_xlfn.NUMBERVALUE(MID(F16,2,FIND(";",F16,1)-2)) -> 0.1673 | G30: =_xlfn.NUMBERVALUE(MID(G16,2,FIND(";",G16,1)-2)) -> 0 | H30: =_xlfn.NUMBERVALUE(MID(H16,2,FIND(";",H16,1)-2)) -> 0.0707 | I30: =_xlfn.NUMBERVALUE(MID(I16,2,FIND(";",I16,1)-2)) -> 0 | ... M30: =_xlfn.NUMBERVALUE(MID(M16,2,FIND(";",M16,1)-2)) -> 0
